Workbook

Sheet Included
A1: First Author | B1: Publication Year | C1: PubMed link | D1: Study name | E1: Included in analysis | F1: Cohort size | G1: Age median | H1: Age min | I1: Age max | J1: Conditioning regimens: RIC | K1: Conditioning regimens: MAC | L1: Conditioning regimens: Unclear | M1: Antiviral PPX: AYC | N1: Antiviral PPX: GAN | O1: Antiviral PPX: FOS | P1: Antiviral PPX: Unclear | Q1: GVHD PPX: Cyclosporine | R1: GVHD PPX: CsA + MMF | S1: GVHD PPX: CsA + MMF + MTX | T1: GVHD PPX: CsA + MTX | U1: GVHD PPX: Cyclophos phamide | V1: GVHD PPX: Cy + CsA + MMF | W1: GVHD PPX: Cy + MMF + Tac or Siro | X1: GVHD PPX: MMF | Y1: GVHD PPX: TAC + MTX | Z1: GVHD PPX: CAMPATH-1 | AA1: GVHD PPX: Unclear | AB1: Tx type: BM | AC1: Tx type: PBSC | AD1: Tx type: CBT | AE1: Tx type: Unclear | AF1: N patients tested for HHV-6 | AG1: N patients with HHV-6 | AH1: N patients with HHV-6 detected after IR failure | AI1: N HHV-6 pos pts with delayed or failed engraftment (broadly) | AJ1: N HHV-6 pos pts with delayed or failed T cell engraftment | AK1: N HHV-6 pos pts with delayed or failed NK cell engraftment | AL1: N HHV-6 pos pts with delayed or failed neutrophil engraftment | AM1: N HHV-6 pos pts with delayed or failed platelet engraftment | AN1: HHV-6 pos min days to neutrophil engraftment | AO1: HHV-6 pos Q1 days to neutrophil engraftment | AP1: HHV-6 pos median days to neutrophil engraftment | AQ1: HHV-6 pos Q3 days to neutrophil engraftment | AR1: HHV-6 pos max days to neutrophil engraftment | AS1: HHV-6 pos min days to platelet engraftment | AT1: HHV-6 pos Q1 days to platelet engraftment | AU1: HHV-6 pos median days to platelet engraftment | AV1: HHV-6 pos Q3 days to platelet engraftment | AW1: HHV-6 pos max days to platelet engraftment | AX1: HHV-6 pos Q1 days to T cell engraftment | AY1: HHV-6 pos median days to T cell engraftment | AZ1: HHV-6 pos Q3 days to T cell engraftment | BA1: Combined HR/MHR neutrophil engraftment | BB1: Combined HR/MHR LB neutrophil engraftment | BC1: Combined HR/MHR UB neutrophil engraftment | BD1: Combined HR/MHR platelet engraftment | BE1: Combined HR/MHR LB platelet engraftment | BF1: Combined HR/MHR UB platelet engraftment | BG1: N patients with HHV-6 who engrafted neutrophils | BH1: N patients without HHV-6 who engrafted neutrophils | BI1: MHR HHV-6 neutrophil engraftment | BJ1: MHR LB HHV-6 neutrophil engraftment | BK1: MHR UB HHV-6 neutrophil engraftment | BL1: N patients with HHV-6 who engrafted platelets | BM1: N patients without HHV-6 who engrafted platelets | BN1: MHR HHV-6 platelets engraftment | BO1: MHR LB HHV-6 platelets engraftment | BP1: MHR UB HHV-6 platelets engraftment | BQ1: HR HHV-6 neutrophil engraftment | BR1: HR LB HHV-6 neutrophil engraftment | BS1: HR UB HHV-6 neutrophil engraftment | BT1: HR HHV-6 platelet engraftment | BU1: HR LB HHV-6 platelet engraftment | BV1: HR UB HHV-6 platelet engraftment | BW1: HR HHV-6 CD4 T cell engraftment | BX1: HR LB HHV-6 CD4 T cell engraftment | BY1: HR UB HHV-6 CD4 T cell engraftment | BZ1: HR HHV-6 CD8 T cell engraftment | CA1: HR LB HHV-6 CD8 T cell engraftment | CB1: HR UB HHV-6 CD8 T cell engraftment | CC1: N patients without HHV-6 | CD1: N HHV-6 neg pts with delayed or failed engraftment (broadly) | CE1: N HHV-6 neg pts with delayed or failed T cell engraftment | CF1: N HHV-6 neg pts with delayed or failed NK cell engraftment | CG1: N HHV-6 neg pts with delayed or failed neutrophil engraftment | CH1: N HHV-6 neg pts with delayed or failed platelet engraftment | CI1: HHV-6 neg min days to neutrophil engraftment | CJ1: HHV-6 neg Q1 days to neutrophil engraftment | CK1: HHV-6 neg median days to neutrophil engraftment | CL1: HHV-6 neg Q3 days to neutrophil engraftment | CM1: HHV-6 neg max days to neutrophil engraftment | CN1: HHV-6 neg min days to platelet engraftment | CO1: HHV-6 neg Q1 days to platelet engraftment | CP1: HHV-6 neg median days to platelet engraftment | CQ1: HHV-6 neg Q3 days to platelet engraftment | CR1: HHV-6 neg max days to platelet engraftment | CS1: HHV-6 neg Q1 days to T cell engraftment | CT1: HHV-6 neg median days to T cell engraftment | CU1: HHV-6 neg Q3 days to T cell engraftment | CV1: Definition of neutrophil reconstitution / engraftment | CW1: Definition of platelet reconstitution / engraftment | CX1: Notes
A2: Betts BC | B2: 2011 | C2: https://pubmed.ncbi.nlm.nih.gov/21549850 | D2: =A2&" "&B2 -> Betts BC 2011 | E2: =IF(OR(AND(ISNUMBER(AG2),ISNUMBER(AL2),ISNUMBER(CC2),ISNUMBER(CG2)),AND(ISNUMBER(AG2),ISNUMBER(AM2),ISNUMBER(CC2),ISNUMBER(CH2))),"Yes","No") -> Yes | F2: 82 | G2: 26 | H2: 1 | I2: 66 | J2: Given for HHV-6 pos but not whole cohort | K2: Given for HHV-6 pos but not whole cohort | P2: 82 | AA2: 82 | AD2: 37 | AE2: =82-37 -> 45 | AF2: 82 | AG2: 46 | AH2: Timing of IR failure relative to HHV-6 detection is unclear, but systemic testing was performed | AI2: 7 | AL2: 7 | BA2: =IF(ISNUMBER(BQ2),BQ2,IF(AND(ISNUMBER($BJ2),ISNUMBER($BK2)),BI2,"")) | BB2: =IF(ISNUMBER(BR2),BR2,IF(AND(ISNUMBER($BJ2),ISNUMBER($BK2)),BJ2,"")) | BC2: =IF(ISNUMBER(BS2),BS2,IF(AND(ISNUMBER($BJ2),ISNUMBER($BK2)),BK2,"")) | BD2: =IF(ISNUMBER(BT2),BT2,IF(AND(ISNUMBER($BO2),ISNUMBER($BP2)),BN2,"")) | BE2: =IF(ISNUMBER(BU2),BU2,IF(AND(ISNUMBER($BO2),ISNUMBER($BP2)),BO2,"")) | BF2: =IF(ISNUMBER(BV2),BV2,IF(AND(ISNUMBER($BO2),ISNUMBER($BP2)),BP2,"")) | BJ2: =IF(AND(ISNUMBER(BG2),ISNUMBER(BH2),ISNUMBER(BI2)),EXP(LOG(BI2)-1.96*SQRT((1/BG2)+(1/BH2))),"") | BK2: =IF(AND(ISNUMBER(BG2),ISNUMBER(BH2),ISNUMBER(BI2)),EXP(LOG(BI2)+1.96*SQRT((1/BG2)+(1/BH2))),"") | BO2: =IF(AND(ISNUMBER(BL2),ISNUMBER(BM2),ISNUMBER(BN2)),EXP(LOG(BN2)-1.96*SQRT((1/BL2)+(1/BM2))),"") | BP2: =IF(AND(ISNUMBER(BL2),ISNUMBER(BM2),ISNUMBER(BN2)),EXP(LOG(BN2)+1.96*SQRT((1/BL2)+(1/BM2))),"") | CC2: 36 | CD2: 4 | CG2: 4 | CV2: Data given as "Bone marrow suppression/delayed engraftment". Bone marrow suppression was defined as recovery of HHV6 from marrow aspirates by PCR, accompanying worsening leukopenia, thrombocytopenia, and a hypoplastic marrow. | CX2: marked broad engraftment as neutrophil
A3: Chan PK | B3: 1997 | C3: https://pubmed.ncbi.nlm.nih.gov/9365899 | D3: =A3&" "&B3 -> Chan PK 1997 | E3: =IF(OR(AND(ISNUMBER(AG3),ISNUMBER(AL3),ISNUMBER(CC3),ISNUMBER(CG3)),AND(ISNUMBER(AG3),ISNUMBER(AM3),ISNUMBER(CC3),ISNUMBER(CH3))),"Yes","No") -> Yes | F3: 61 | G3: Unclear | H3: Unclear | I3: Unclear | K3: 33 | L3: =61-33 -> 28 | P3: 61 | AA3: 61 | AB3: 61 | AF3: 61 | AG3: 17 | AH3: Timing of IR failure relative to HHV-6 detection is unclear, but systemic testing was performed | AL3: 1 | BA3: =IF(ISNUMBER(BQ3),BQ3,IF(AND(ISNUMBER($BJ3),ISNUMBER($BK3)),BI3,"")) | BB3: =IF(ISNUMBER(BR3),BR3,IF(AND(ISNUMBER($BJ3),ISNUMBER($BK3)),BJ3,"")) | BC3: =IF(ISNUMBER(BS3),BS3,IF(AND(ISNUMBER($BJ3),ISNUMBER($BK3)),BK3,"")) | BD3: =IF(ISNUMBER(BT3),BT3,IF(AND(ISNUMBER($BO3),ISNUMBER($BP3)),BN3,"")) | BE3: =IF(ISNUMBER(BU3),BU3,IF(AND(ISNUMBER($BO3),ISNUMBER($BP3)),BO3,"")) | BF3: =IF(ISNUMBER(BV3),BV3,IF(AND(ISNUMBER($BO3),ISNUMBER($BP3)),BP3,"")) | BJ3: =IF(AND(ISNUMBER(BG3),ISNUMBER(BH3),ISNUMBER(BI3)),EXP(LOG(BI3)-1.96*SQRT((1/BG3)+(1/BH3))),"") | BK3: =IF(AND(ISNUMBER(BG3),ISNUMBER(BH3),ISNUMBER(BI3)),EXP(LOG(BI3)+1.96*SQRT((1/BG3)+(1/BH3))),"") | BO3: =IF(AND(ISNUMBER(BL3),ISNUMBER(BM3),ISNUMBER(BN3)),EXP(LOG(BN3)-1.96*SQRT((1/BL3)+(1/BM3))),"") | BP3: =IF(AND(ISNUMBER(BL3),ISNUMBER(BM3),ISNUMBER(BN3)),EXP(LOG(BN3)+1.96*SQRT((1/BL3)+(1/BM3))),"") | CC3: 44 | CG3: 1 | CV3: The date of engraftment of the transplanted marrow was defined as the first day post-transplantation when the absolute neutrophil count was >500 cells/ml of blood.
A4: Drobyski WR | B4: 1993 | C4: https://pubmed.ncbi.nlm.nih.gov/8382723 | D4: =A4&" "&B4 -> Drobyski WR 1993 | E4: =IF(OR(AND(ISNUMBER(AG4),ISNUMBER(AL4),ISNUMBER(CC4),ISNUMBER(CG4)),AND(ISNUMBER(AG4),ISNUMBER(AM4),ISNUMBER(CC4),ISNUMBER(CH4))),"Yes","No") -> Yes | F4: 16 | G4: ND | H4: ND | I4: ND | K4: 16 | M4: 16 | Q4: 16 | AB4: 16 | AF4: 16 | AG4: 6 | AH4: Timing of IR failure relative to HHV-6 detection is unclear | AL4: 1 | BA4: =IF(ISNUMBER(BQ4),BQ4,IF(AND(ISNUMBER($BJ4),ISNUMBER($BK4)),BI4,"")) | BB4: =IF(ISNUMBER(BR4),BR4,IF(AND(ISNUMBER($BJ4),ISNUMBER($BK4)),BJ4,"")) | BC4: =IF(ISNUMBER(BS4),BS4,IF(AND(ISNUMBER($BJ4),ISNUMBER($BK4)),BK4,"")) | BD4: =IF(ISNUMBER(BT4),BT4,IF(AND(ISNUMBER($BO4),ISNUMBER($BP4)),BN4,"")) | BE4: =IF(ISNUMBER(BU4),BU4,IF(AND(ISNUMBER($BO4),ISNUMBER($BP4)),BO4,"")) | BF4: =IF(ISNUMBER(BV4),BV4,IF(AND(ISNUMBER($BO4),ISNUMBER($BP4)),BP4,"")) | BJ4: =IF(AND(ISNUMBER(BG4),ISNUMBER(BH4),ISNUMBER(BI4)),EXP(LOG(BI4)-1.96*SQRT((1/BG4)+(1/BH4))),"") | BK4: =IF(AND(ISNUMBER(BG4),ISNUMBER(BH4),ISNUMBER(BI4)),EXP(LOG(BI4)+1.96*SQRT((1/BG4)+(1/BH4))),"") | BO4: =IF(AND(ISNUMBER(BL4),ISNUMBER(BM4),ISNUMBER(BN4)),EXP(LOG(BN4)-1.96*SQRT((1/BL4)+(1/BM4))),"") | BP4: =IF(AND(ISNUMBER(BL4),ISNUMBER(BM4),ISNUMBER(BN4)),EXP(LOG(BN4)+1.96*SQRT((1/BL4)+(1/BM4))),"") | CC4: =16-6 -> 10 | CG4: 0 | CV4: Engraftment in this patient population was considered to have occurred when there were 3 consecutive days with an absolute neutrophil count (ANC) ~500/mm3.
A5: Düver F | B5: 2020 | C5: https://pubmed.ncbi.nlm.nih.gov/32017805 | D5: =A5&" "&B5 -> Düver F 2020 | E5: =IF(OR(AND(ISNUMBER(AG5),ISNUMBER(AL5),ISNUMBER(CC5),ISNUMBER(CG5)),AND(ISNUMBER(AG5),ISNUMBER(AM5),ISNUMBER(CC5),ISNUMBER(CH5))),"Yes","No") -> Yes | F5: 107 | G5: 9 | H5: Unclear | I5: Unclear | K5: 107 | M5: =F5 -> 107 | Q5: =ROUND(F5*0.822,0) -> 88 | AB5: 20 | AC5: =F5-AB5 -> 87 | AG5: 36 | AH5: 0 | AI5: 1 | AL5: 1 | BA5: =IF(ISNUMBER(BQ5),BQ5,IF(AND(ISNUMBER($BJ5),ISNUMBER($BK5)),BI5,"")) | BB5: =IF(ISNUMBER(BR5),BR5,IF(AND(ISNUMBER($BJ5),ISNUMBER($BK5)),BJ5,"")) | BC5: =IF(ISNUMBER(BS5),BS5,IF(AND(ISNUMBER($BJ5),ISNUMBER($BK5)),BK5,"")) | BD5: =IF(ISNUMBER(BT5),BT5,IF(AND(ISNUMBER($BO5),ISNUMBER($BP5)),BN5,"")) | BE5: =IF(ISNUMBER(BU5),BU5,IF(AND(ISNUMBER($BO5),ISNUMBER($BP5)),BO5,"")) | BF5: =IF(ISNUMBER(BV5),BV5,IF(AND(ISNUMBER($BO5),ISNUMBER($BP5)),BP5,"")) | BJ5: =IF(AND(ISNUMBER(BG5),ISNUMBER(BH5),ISNUMBER(BI5)),EXP(LOG(BI5)-1.96*SQRT((1/BG5)+(1/BH5))),"") | BK5: =IF(AND(ISNUMBER(BG5),ISNUMBER(BH5),ISNUMBER(BI5)),EXP(LOG(BI5)+1.96*SQRT((1/BG5)+(1/BH5))),"") | BO5: =IF(AND(ISNUMBER(BL5),ISNUMBER(BM5),ISNUMBER(BN5)),EXP(LOG(BN5)-1.96*SQRT((1/BL5)+(1/BM5))),"") | BP5: =IF(AND(ISNUMBER(BL5),ISNUMBER(BM5),ISNUMBER(BN5)),EXP(LOG(BN5)+1.96*SQRT((1/BL5)+(1/BM5))),"") | CC5: =107-36 -> 71 | CD5: 2 | CG5: 2 | CV5: Engraftment was defined as the first of three consecutive days with a leukocyte count above 1000/μl in peripheral blood samples. | CX5: marked broad engraftment as neutrophil
A6: Dzieciątkowski T | B6: 2010 | C6: https://pubmed.ncbi.nlm.nih.gov/20872080 | D6: =A6&" "&B6 -> Dzieciątkowski T 2010 | E6: =IF(OR(AND(ISNUMBER(AG6),ISNUMBER(AL6),ISNUMBER(CC6),ISNUMBER(CG6)),AND(ISNUMBER(AG6),ISNUMBER(AM6),ISNUMBER(CC6),ISNUMBER(CH6))),"Yes","No") -> Yes | F6: 7 | G6: =MEDIAN(18,27,22,20,32,27,44) -> 27 | H6: =MIN(18,27,22,20,32,27,44) -> 18 | I6: =MAX(18,27,22,20,32,27,44) -> 44 | L6: 7 | M6: 7 | AA6: 7 | AD6: 7 | AG6: 1 | AH6: 0 | AI6: 0 | AL6: 0 | BA6: =IF(ISNUMBER(BQ6),BQ6,IF(AND(ISNUMBER($BJ6),ISNUMBER($BK6)),BI6,"")) | BB6: =IF(ISNUMBER(BR6),BR6,IF(AND(ISNUMBER($BJ6),ISNUMBER($BK6)),BJ6,"")) | BC6: =IF(ISNUMBER(BS6),BS6,IF(AND(ISNUMBER($BJ6),ISNUMBER($BK6)),BK6,"")) | BD6: =IF(ISNUMBER(BT6),BT6,IF(AND(ISNUMBER($BO6),ISNUMBER($BP6)),BN6,"")) | BE6: =IF(ISNUMBER(BU6),BU6,IF(AND(ISNUMBER($BO6),ISNUMBER($BP6)),BO6,"")) | BF6: =IF(ISNUMBER(BV6),BV6,IF(AND(ISNUMBER($BO6),ISNUMBER($BP6)),BP6,"")) | BJ6: =IF(AND(ISNUMBER(BG6),ISNUMBER(BH6),ISNUMBER(BI6)),EXP(LOG(BI6)-1.96*SQRT((1/BG6)+(1/BH6))),"") | BK6: =IF(AND(ISNUMBER(BG6),ISNUMBER(BH6),ISNUMBER(BI6)),EXP(LOG(BI6)+1.96*SQRT((1/BG6)+(1/BH6))),"") | BO6: =IF(AND(ISNUMBER(BL6),ISNUMBER(BM6),ISNUMBER(BN6)),EXP(LOG(BN6)-1.96*SQRT((1/BL6)+(1/BM6))),"") | BP6: =IF(AND(ISNUMBER(BL6),ISNUMBER(BM6),ISNUMBER(BN6)),EXP(LOG(BN6)+1.96*SQRT((1/BL6)+(1/BM6))),"") | CC6: 6 | CD6: 1 | CG6: 1 | CV6: Not discussed. "acceptable engraftment" only mention | CX6: marked broad engraftment as neutrophil
A7: El Jurdi N | B7: 2021 | C7: https://pubmed.ncbi.nlm.nih.gov/33053448 | D7: =A7&" "&B7 -> El Jurdi N 2021 | E7: =IF(OR(AND(ISNUMBER(AG7),ISNUMBER(AL7),ISNUMBER(CC7),ISNUMBER(CG7)),AND(ISNUMBER(AG7),ISNUMBER(AM7),ISNUMBER(CC7),ISNUMBER(CH7))),"Yes","No") -> Yes | F7: 86 | G7: Unclear | H7: Unclear | I7: Unclear | J7: =16+9+31+30 -> 86 | M7: 86 | X7: =25+61 -> 86 | AD7: =4+11+10+1+5+55 -> 86 | AG7: =ROUND(F7*0.63,0) -> 54 | AH7: 0 | AL7: 11 | AM7: 13 | BA7: =IF(ISNUMBER(BQ7),BQ7,IF(AND(ISNUMBER($BJ7),ISNUMBER($BK7)),BI7,"")) | BB7: =IF(ISNUMBER(BR7),BR7,IF(AND(ISNUMBER($BJ7),ISNUMBER($BK7)),BJ7,"")) | BC7: =IF(ISNUMBER(BS7),BS7,IF(AND(ISNUMBER($BJ7),ISNUMBER($BK7)),BK7,"")) | BD7: =IF(ISNUMBER(BT7),BT7,IF(AND(ISNUMBER($BO7),ISNUMBER($BP7)),BN7,"")) | BE7: =IF(ISNUMBER(BU7),BU7,IF(AND(ISNUMBER($BO7),ISNUMBER($BP7)),BO7,"")) | BF7: =IF(ISNUMBER(BV7),BV7,IF(AND(ISNUMBER($BO7),ISNUMBER($BP7)),BP7,"")) | BJ7: =IF(AND(ISNUMBER(BG7),ISNUMBER(BH7),ISNUMBER(BI7)),EXP(LOG(BI7)-1.96*SQRT((1/BG7)+(1/BH7))),"") | BK7: =IF(AND(ISNUMBER(BG7),ISNUMBER(BH7),ISNUMBER(BI7)),EXP(LOG(BI7)+1.96*SQRT((1/BG7)+(1/BH7))),"") | BO7: =IF(AND(ISNUMBER(BL7),ISNUMBER(BM7),ISNUMBER(BN7)),EXP(LOG(BN7)-1.96*SQRT((1/BL7)+(1/BM7))),"") | BP7: =IF(AND(ISNUMBER(BL7),ISNUMBER(BM7),ISNUMBER(BN7)),EXP(LOG(BN7)+1.96*SQRT((1/BL7)+(1/BM7))),"") | CC7: =F7-AG7 -> 32 | CG7: 5 | CH7: =17-13 -> 4 | CV7: "Neutrophil engraftment was defined as absolute neutrophil count >=5 x 10^8/L on the first of 3 consecutive measurements." | CW7: "Platelet engraftment was defined as the first of 7 consecutive days with a nontransfused count of >=20 x 10^9/L."
A8: Gomes de Oliveira PG | B8: 2016 | C8: https://pubmed.ncbi.nlm.nih.gov/26555946 | D8: =A8&" "&B8 -> Gomes de Oliveira PG 2016 | E8: =IF(OR(AND(ISNUMBER(AG8),ISNUMBER(AL8),ISNUMBER(CC8),ISNUMBER(CG8)),AND(ISNUMBER(AG8),ISNUMBER(AM8),ISNUMBER(CC8),ISNUMBER(CH8))),"Yes","No") -> Yes | F8: 98 | G8: 16 | H8: 2 | I8: 73 | J8: 27 | L8: =F8-J8 -> 71 | M8: 98 | Q8: 17 | R8: 36 | T8: 24 | U8: 9 | AA8: 47 | AD8: 24 | AE8: 74 | AF8: 98 | AG8: 18 | AH8: 0 | AL8: =ROUND(AG8*(1-0.82),0) -> 3 | AM8: =ROUND(AG8*(1-0.71),0) -> 5 | AP8: 19 | AU8: 38 | BA8: =IF(ISNUMBER(BQ8),BQ8,IF(AND(ISNUMBER($BJ8),ISNUMBER($BK8)),BI8,"")) -> 0.84210526 | BB8: =IF(ISNUMBER(BR8),BR8,IF(AND(ISNUMBER($BJ8),ISNUMBER($BK8)),BJ8,"")) -> 0.53376261 | BC8: =IF(ISNUMBER(BS8),BS8,IF(AND(ISNUMBER($BJ8),ISNUMBER($BK8)),BK8,"")) -> 1.6137116 | BD8: =IF(ISNUMBER(BT8),BT8,IF(AND(ISNUMBER($BO8),ISNUMBER($BP8)),BN8,"")) -> 0.47368421 | BE8: =IF(ISNUMBER(BU8),BU8,IF(AND(ISNUMBER($BO8),ISNUMBER($BP8)),BO8,"")) -> 0.4007015 | BF8: =IF(ISNUMBER(BV8),BV8,IF(AND(ISNUMBER($BO8),ISNUMBER($BP8)),BP8,"")) -> 1.3041041 | BG8: =ROUND(AG8*0.82,0) -> 15 | BH8: =ROUND(CC8*0.96,0) -> 77 | BI8: =CK8/AP8 -> 0.84210526 | BJ8: =IF(AND(ISNUMBER(BG8),ISNUMBER(BH8),ISNUMBER(BI8)),EXP(LOG(BI8)-1.96*SQRT((1/BG8)+(1/BH8))),"") -> 0.53376261 | BK8: =IF(AND(ISNUMBER(BG8),ISNUMBER(BH8),ISNUMBER(BI8)),EXP(LOG(BI8)+1.96*SQRT((1/BG8)+(1/BH8))),"") -> 1.6137116 | BL8: =ROUND(AG8*0.71,0) -> 13 | BM8: =ROUND(CC8*0.91,0) -> 73 | BN8: =CP8/AU8 -> 0.47368421 | BO8: =IF(AND(ISNUMBER(BL8),ISNUMBER(BM8),ISNUMBER(BN8)),EXP(LOG(BN8)-1.96*SQRT((1/BL8)+(1/BM8))),"") -> 0.4007015 | BP8: =IF(AND(ISNUMBER(BL8),ISNUMBER(BM8),ISNUMBER(BN8)),EXP(LOG(BN8)+1.96*SQRT((1/BL8)+(1/BM8))),"") -> 1.3041041 | CC8: =F8-AG8 -> 80 | CG8: =ROUND(CC8*(1-0.96),0) -> 3 | CH8: =ROUND(CC8*(1-0.91),0) -> 7 | CK8: 16 | CP8: 18 | CV8: "... first of 3 consecutive days with a neutrophil count of at least 0.5 x 10^9/L" | CW8: "... first of 7 consecutive days of an unsupported platelet count of at least 20 x 10^9/L"
A9: Han TT | B9: 2021 | C9: https://pubmed.ncbi.nlm.nih.gov/33326670 | D9: =A9&" "&B9 -> Han TT 2021 | E9: =IF(OR(AND(ISNUMBER(AG9),ISNUMBER(AL9),ISNUMBER(CC9),ISNUMBER(CG9)),AND(ISNUMBER(AG9),ISNUMBER(AM9),ISNUMBER(CC9),ISNUMBER(CH9))),"Yes","No") -> Yes | F9: 102 | G9: 25 | H9: 2 | I9: 58 | M9: =F9 -> 102 | S9: =F9 -> 102 | AE9: =F9 -> 102 | AF9: 102 | AG9: 25 | AH9: Timing of IR failure relative to HHV-6 detection is unclear, but systemic testing was performed | AM9: 4 | AN9: 9 | AP9: 13 | AR9: 21 | AS9: 9 | AU9: 16 | AW9: 29 | BA9: =IF(ISNUMBER(BQ9),BQ9,IF(AND(ISNUMBER($BJ9),ISNUMBER($BK9)),BI9,"")) | BB9: =IF(ISNUMBER(BR9),BR9,IF(AND(ISNUMBER($BJ9),ISNUMBER($BK9)),BJ9,"")) | BC9: =IF(ISNUMBER(BS9),BS9,IF(AND(ISNUMBER($BJ9),ISNUMBER($BK9)),BK9,"")) | BD9: =IF(ISNUMBER(BT9),BT9,IF(AND(ISNUMBER($BO9),ISNUMBER($BP9)),BN9,"")) -> 1 | BE9: =IF(ISNUMBER(BU9),BU9,IF(AND(ISNUMBER($BO9),ISNUMBER($BP9)),BO9,"")) -> 0.61454819 | BF9: =IF(ISNUMBER(BV9),BV9,IF(AND(ISNUMBER($BO9),ISNUMBER($BP9)),BP9,"")) -> 1.6272117 | BG9: Unclear | BH9: Unclear | BI9: =CK9/AP9 -> 1 | BJ9: =IF(AND(ISNUMBER(BG9),ISNUMBER(BH9),ISNUMBER(BI9)),EXP(LOG(BI9)-1.96*SQRT((1/BG9)+(1/BH9))),"") | BK9: =IF(AND(ISNUMBER(BG9),ISNUMBER(BH9),ISNUMBER(BI9)),EXP(LOG(BI9)+1.96*SQRT((1/BG9)+(1/BH9))),"") | BL9: =AG9-4 -> 21 | BM9: =CC9-6 -> 71 | BN9: =CP9/AU9 -> 1 | BO9: =IF(AND(ISNUMBER(BL9),ISNUMBER(BM9),ISNUMBER(BN9)),EXP(LOG(BN9)-1.96*SQRT((1/BL9)+(1/BM9))),"") -> 0.61454819 | BP9: =IF(AND(ISNUMBER(BL9),ISNUMBER(BM9),ISNUMBER(BN9)),EXP(LOG(BN9)+1.96*SQRT((1/BL9)+(1/BM9))),"") -> 1.6272117 | CC9: 77 | CH9: 6 | CI9: 11 | CK9: 13 | CM9: 20 | CN9: 10 | CP9: 16 | CR9: 84 | CV9: "The date of white blood cell (WBC) and platelet engraftment were defined as accepted standards" | CW9: "The date of white blood cell (WBC) and platelet engraftment were defined as accepted standards."
A10: Hentrich M | B10: 2005 | C10: https://pubmed.ncbi.nlm.nih.gov/15606551 | D10: =A10&" "&B10 -> Hentrich M 2005 | E10: =IF(OR(AND(ISNUMBER(AG10),ISNUMBER(AL10),ISNUMBER(CC10),ISNUMBER(CG10)),AND(ISNUMBER(AG10),ISNUMBER(AM10),ISNUMBER(CC10),ISNUMBER(CH10))),"Yes","No") -> Yes | F10: =129+99 -> 228 | G10: Unclear | H10: Unclear | I10: Unclear | K10: =F10 -> 228 | M10: =F10 -> 228 | AA10: =F10 -> 228 | AB10: =100+63 -> 163 | AC10: =21+13 -> 34 | AF10: =129+99 -> 228 | AG10: 129 | AH10: 0 | AL10: 8 | AP10: 19 | BA10: =IF(ISNUMBER(BQ10),BQ10,IF(AND(ISNUMBER($BJ10),ISNUMBER($BK10)),BI10,"")) | BB10: =IF(ISNUMBER(BR10),BR10,IF(AND(ISNUMBER($BJ10),ISNUMBER($BK10)),BJ10,"")) | BC10: =IF(ISNUMBER(BS10),BS10,IF(AND(ISNUMBER($BJ10),ISNUMBER($BK10)),BK10,"")) | BD10: =IF(ISNUMBER(BT10),BT10,IF(AND(ISNUMBER($BO10),ISNUMBER($BP10)),BN10,"")) | BE10: =IF(ISNUMBER(BU10),BU10,IF(AND(ISNUMBER($BO10),ISNUMBER($BP10)),BO10,"")) | BF10: =IF(ISNUMBER(BV10),BV10,IF(AND(ISNUMBER($BO10),ISNUMBER($BP10)),BP10,"")) | BG10: Unclear | BH10: Unclear | BI10: =CK10/AP10 -> 0.94736842 | BJ10: =IF(AND(ISNUMBER(BG10),ISNUMBER(BH10),ISNUMBER(BI10)),EXP(LOG(BI10)-1.96*SQRT((1/BG10)+(1/BH10))),"") | BK10: =IF(AND(ISNUMBER(BG10),ISNUMBER(BH10),ISNUMBER(BI10)),EXP(LOG(BI10)+1.96*SQRT((1/BG10)+(1/BH10))),"") | BO10: =IF(AND(ISNUMBER(BL10),ISNUMBER(BM10),ISNUMBER(BN10)),EXP(LOG(BN10)-1.96*SQRT((1/BL10)+(1/BM10))),"") | BP10: =IF(AND(ISNUMBER(BL10),ISNUMBER(BM10),ISNUMBER(BN10)),EXP(LOG(BN10)+1.96*SQRT((1/BL10)+(1/BM10))),"") | CC10: 99 | CG10: 11 | CK10: 18 | CV10: "Delayed engraftment was defined as an ANC of 0.5 x10^9/L first occurring on or after day +25 after HSCT." | CX10: Median is inferred here. Engraftment is not explicilty given as the median, but in context I think this is a reasonable assumption (no averages are given in the paper, only medians)
A11: Le Bourgeois A | B11: 2014 | C11: https://pubmed.ncbi.nlm.nih.gov/25072620 | D11: =A11&" "&B11 -> Le Bourgeois A 2014 | E11: =IF(OR(AND(ISNUMBER(AG11),ISNUMBER(AL11),ISNUMBER(CC11),ISNUMBER(CG11)),AND(ISNUMBER(AG11),ISNUMBER(AM11),ISNUMBER(CC11),ISNUMBER(CH11))),"Yes","No") -> Yes | F11: 73 | G11: Unclear | H11: Unclear | I11: Unclear | J11: 69 | K11: 8 | P11: =F11 -> 73 | R11: =F11 -> 73 | AD11: =F11 -> 73 | AG11: 27 | AH11: 0 | AL11: 9 | BA11: =IF(ISNUMBER(BQ11),BQ11,IF(AND(ISNUMBER($BJ11),ISNUMBER($BK11)),BI11,"")) | BB11: =IF(ISNUMBER(BR11),BR11,IF(AND(ISNUMBER($BJ11),ISNUMBER($BK11)),BJ11,"")) | BC11: =IF(ISNUMBER(BS11),BS11,IF(AND(ISNUMBER($BJ11),ISNUMBER($BK11)),BK11,"")) | BD11: =IF(ISNUMBER(BT11),BT11,IF(AND(ISNUMBER($BO11),ISNUMBER($BP11)),BN11,"")) | BE11: =IF(ISNUMBER(BU11),BU11,IF(AND(ISNUMBER($BO11),ISNUMBER($BP11)),BO11,"")) | BF11: =IF(ISNUMBER(BV11),BV11,IF(AND(ISNUMBER($BO11),ISNUMBER($BP11)),BP11,"")) | BJ11: =IF(AND(ISNUMBER(BG11),ISNUMBER(BH11),ISNUMBER(BI11)),EXP(LOG(BI11)-1.96*SQRT((1/BG11)+(1/BH11))),"") | BK11: =IF(AND(ISNUMBER(BG11),ISNUMBER(BH11),ISNUMBER(BI11)),EXP(LOG(BI11)+1.96*SQRT((1/BG11)+(1/BH11))),"") | BO11: =IF(AND(ISNUMBER(BL11),ISNUMBER(BM11),ISNUMBER(BN11)),EXP(LOG(BN11)-1.96*SQRT((1/BL11)+(1/BM11))),"") | BP11: =IF(AND(ISNUMBER(BL11),ISNUMBER(BM11),ISNUMBER(BN11)),EXP(LOG(BN11)+1.96*SQRT((1/BL11)+(1/BM11))),"") | CC11: 44 | CG11: 6 | CV11: "Neutrophil recovery was defined as the first of three consecutive days during which the absolute neutrophil count in the blood was >0.5 x 10^9/L. " | CW11: "Platelet recovery was defined as the first of three consecutive days when the platelet count was >20 x 10^9/L without transfusion support."
A12: Mata JR | B12: 2024 | C12: https://pubmed.ncbi.nlm.nih.gov/38521411 | D12: =A12&" "&B12 -> Mata JR 2024 | E12: =IF(OR(AND(ISNUMBER(AG12),ISNUMBER(AL12),ISNUMBER(CC12),ISNUMBER(CG12)),AND(ISNUMBER(AG12),ISNUMBER(AM12),ISNUMBER(CC12),ISNUMBER(CH12))),"Yes","No") -> Yes | F12: 958 | G12: Unclear | H12: 18 | I12: Unclear | J12: Unclear | K12: Unclear | L12: Unclear | P12: =F12 -> 958 | W12: =F12 -> 958 | AB12: 455 | AC12: 503 | AF12: 958 | AG12: =193+17 -> 210 | AI12: 17 | AL12: 17 | BA12: =IF(ISNUMBER(BQ12),BQ12,IF(AND(ISNUMBER($BJ12),ISNUMBER($BK12)),BI12,"")) | BB12: =IF(ISNUMBER(BR12),BR12,IF(AND(ISNUMBER($BJ12),ISNUMBER($BK12)),BJ12,"")) | BC12: =IF(ISNUMBER(BS12),BS12,IF(AND(ISNUMBER($BJ12),ISNUMBER($BK12)),BK12,"")) | BD12: =IF(ISNUMBER(BT12),BT12,IF(AND(ISNUMBER($BO12),ISNUMBER($BP12)),BN12,"")) | BE12: =IF(ISNUMBER(BU12),BU12,IF(AND(ISNUMBER($BO12),ISNUMBER($BP12)),BO12,"")) | BF12: =IF(ISNUMBER(BV12),BV12,IF(AND(ISNUMBER($BO12),ISNUMBER($BP12)),BP12,"")) | CC12: =921-193 -> 728 | CD12: =37-17 -> 20 | CG12: =37-17 -> 20 | CV12: "Normal engraftment was defined as the achievement of an ANC of 500 cells/m3 or greater by day 30" | CX12: Added 7/8/24
A13: Miranda-Silva W | B13: 2023 | C13: https://pubmed.ncbi.nlm.nih.gov/34523191 | D13: =A13&" "&B13 -> Miranda-Silva W 2023 | E13: =IF(OR(AND(ISNUMBER(AG13),ISNUMBER(AL13),ISNUMBER(CC13),ISNUMBER(CG13)),AND(ISNUMBER(AG13),ISNUMBER(AM13),ISNUMBER(CC13),ISNUMBER(CH13))),"Yes","No") -> Yes | F13: 31 | G13: 50 | H13: 19 | I13: 72 | J13: 19 | K13: 12 | M13: =F13 -> 31 | R13: 11 | T13: 10 | V13: 10 | AB13: 10 | AC13: 21 | AF13: 31 | AG13: 2 | AH13: 0 | AL13: 1 | BA13: =IF(ISNUMBER(BQ13),BQ13,IF(AND(ISNUMBER($BJ13),ISNUMBER($BK13)),BI13,"")) | BB13: =IF(ISNUMBER(BR13),BR13,IF(AND(ISNUMBER($BJ13),ISNUMBER($BK13)),BJ13,"")) | BC13: =IF(ISNUMBER(BS13),BS13,IF(AND(ISNUMBER($BJ13),ISNUMBER($BK13)),BK13,"")) | BD13: =IF(ISNUMBER(BT13),BT13,IF(AND(ISNUMBER($BO13),ISNUMBER($BP13)),BN13,"")) | BE13: =IF(ISNUMBER(BU13),BU13,IF(AND(ISNUMBER($BO13),ISNUMBER($BP13)),BO13,"")) | BF13: =IF(ISNUMBER(BV13),BV13,IF(AND(ISNUMBER($BO13),ISNUMBER($BP13)),BP13,"")) | BJ13: =IF(AND(ISNUMBER(BG13),ISNUMBER(BH13),ISNUMBER(BI13)),EXP(LOG(BI13)-1.96*SQRT((1/BG13)+(1/BH13))),"") | BK13: =IF(AND(ISNUMBER(BG13),ISNUMBER(BH13),ISNUMBER(BI13)),EXP(LOG(BI13)+1.96*SQRT((1/BG13)+(1/BH13))),"") | BO13: =IF(AND(ISNUMBER(BL13),ISNUMBER(BM13),ISNUMBER(BN13)),EXP(LOG(BN13)-1.96*SQRT((1/BL13)+(1/BM13))),"") | BP13: =IF(AND(ISNUMBER(BL13),ISNUMBER(BM13),ISNUMBER(BN13)),EXP(LOG(BN13)+1.96*SQRT((1/BL13)+(1/BM13))),"") | CC13: =AF13-AG13 -> 29 | CG13: =ROUND(CC13*(1-0.97),0) -> 1 | CV13: "Neutrophil engraftment was considered as the first day of 3 consecutive days with a neutrophil count of at least 0.5 × 10^9/L" | CW13: "... platelet engraftment was considered as the first day of 7 consecutive days of an unsupported platelet count of at least 20.0 × 10^9/L"
A14: Ogata M | B14: 2006 | C14: https://pubmed.ncbi.nlm.nih.gov/16323134 | D14: =A14&" "&B14 -> Ogata M 2006 | E14: =IF(OR(AND(ISNUMBER(AG14),ISNUMBER(AL14),ISNUMBER(CC14),ISNUMBER(CG14)),AND(ISNUMBER(AG14),ISNUMBER(AM14),ISNUMBER(CC14),ISNUMBER(CH14))),"Yes","No") -> Yes | F14: =24+26 -> 50 | G14: 40.5 | H14: 12 | I14: 59 | J14: 4 | K14: 46 | M14: 50 | Q14: 1 | T14: 46 | Y14: 3 | AB14: =11+31 -> 42 | AC14: 8 | AF14: =24+26 -> 50 | AG14: 24 | AH14: Timing of IR failure relative to HHV-6 detection is unclear, but systemic testing was performed | AM14: 11 | AN14: 11 | AP14: 14 | AR14: 27 | BA14: =IF(ISNUMBER(BQ14),BQ14,IF(AND(ISNUMBER($BJ14),ISNUMBER($BK14)),BI14,"")) -> 1.0357143 | BB14: =IF(ISNUMBER(BR14),BR14,IF(AND(ISNUMBER($BJ14),ISNUMBER($BK14)),BJ14,"")) -> 0.58299552 | BC14: =IF(ISNUMBER(BS14),BS14,IF(AND(ISNUMBER($BJ14),ISNUMBER($BK14)),BK14,"")) -> 1.7683656 | BD14: =IF(ISNUMBER(BT14),BT14,IF(AND(ISNUMBER($BO14),ISNUMBER($BP14)),BN14,"")) | BE14: =IF(ISNUMBER(BU14),BU14,IF(AND(ISNUMBER($BO14),ISNUMBER($BP14)),BO14,"")) | BF14: =IF(ISNUMBER(BV14),BV14,IF(AND(ISNUMBER($BO14),ISNUMBER($BP14)),BP14,"")) | BG14: =AG14 -> 24 | BH14: =CC14 -> 26 | BI14: =CK14/AP14 -> 1.0357143 | BJ14: =IF(AND(ISNUMBER(BG14),ISNUMBER(BH14),ISNUMBER(BI14)),EXP(LOG(BI14)-1.96*SQRT((1/BG14)+(1/BH14))),"") -> 0.58299552 | BK14: =IF(AND(ISNUMBER(BG14),ISNUMBER(BH14),ISNUMBER(BI14)),EXP(LOG(BI14)+1.96*SQRT((1/BG14)+(1/BH14))),"") -> 1.7683656 | BO14: =IF(AND(ISNUMBER(BL14),ISNUMBER(BM14),ISNUMBER(BN14)),EXP(LOG(BN14)-1.96*SQRT((1/BL14)+(1/BM14))),"") | BP14: =IF(AND(ISNUMBER(BL14),ISNUMBER(BM14),ISNUMBER(BN14)),EXP(LOG(BN14)+1.96*SQRT((1/BL14)+(1/BM14))),"") | CC14: 26 | CH14: 8 | CI14: 11 | CK14: 14.5 | CM14: 25 | CV14: "Neutrophil engraftment was defined as an absolute neutrophil count of > 0.5 x 10^9 neutrophils/L" | CW14: "... platelet engraftment was considered present with a self-sustained platelet count of 20_x0001_x 10^9 platelets/L."
A15: Ohyashiki JH | B15: 2000 | C15: https://pubmed.ncbi.nlm.nih.gov/10998432 | D15: =A15&" "&B15 -> Ohyashiki JH 2000 | E15: =IF(OR(AND(ISNUMBER(AG15),ISNUMBER(AL15),ISNUMBER(CC15),ISNUMBER(CG15)),AND(ISNUMBER(AG15),ISNUMBER(AM15),ISNUMBER(CC15),ISNUMBER(CH15))),"Yes","No") -> Yes | F15: 5 | G15: =MEDIAN(18,45,26,22,28) -> 26 | H15: =MIN(18,45,26,22,28) -> 18 | I15: =MAX(18,45,26,22,28) -> 45 | L15: =F15 -> 5 | P15: =F15 -> 5 | AA15: =F15 -> 5 | AB15: 5 | AF15: 5 | AG15: 3 | AH15: 0 | AM15: 1 | BA15: =IF(ISNUMBER(BQ15),BQ15,IF(AND(ISNUMBER($BJ15),ISNUMBER($BK15)),BI15,"")) | BB15: =IF(ISNUMBER(BR15),BR15,IF(AND(ISNUMBER($BJ15),ISNUMBER($BK15)),BJ15,"")) | BC15: =IF(ISNUMBER(BS15),BS15,IF(AND(ISNUMBER($BJ15),ISNUMBER($BK15)),BK15,"")) | BD15: =IF(ISNUMBER(BT15),BT15,IF(AND(ISNUMBER($BO15),ISNUMBER($BP15)),BN15,"")) | BE15: =IF(ISNUMBER(BU15),BU15,IF(AND(ISNUMBER($BO15),ISNUMBER($BP15)),BO15,"")) | BF15: =IF(ISNUMBER(BV15),BV15,IF(AND(ISNUMBER($BO15),ISNUMBER($BP15)),BP15,"")) | BJ15: =IF(AND(ISNUMBER(BG15),ISNUMBER(BH15),ISNUMBER(BI15)),EXP(LOG(BI15)-1.96*SQRT((1/BG15)+(1/BH15))),"") | BK15: =IF(AND(ISNUMBER(BG15),ISNUMBER(BH15),ISNUMBER(BI15)),EXP(LOG(BI15)+1.96*SQRT((1/BG15)+(1/BH15))),"") | BO15: =IF(AND(ISNUMBER(BL15),ISNUMBER(BM15),ISNUMBER(BN15)),EXP(LOG(BN15)-1.96*SQRT((1/BL15)+(1/BM15))),"") | BP15: =IF(AND(ISNUMBER(BL15),ISNUMBER(BM15),ISNUMBER(BN15)),EXP(LOG(BN15)+1.96*SQRT((1/BL15)+(1/BM15))),"") | CC15: 2 | CH15: 0 | CV15: Not defined
A16: Paviglianiti A | B16: 2024 | C16: https://pubmed.ncbi.nlm.nih.gov/38817703 | D16: =A16&" "&B16 -> Paviglianiti A 2024 | E16: =IF(OR(AND(ISNUMBER(AG16),ISNUMBER(AL16),ISNUMBER(CC16),ISNUMBER(CG16)),AND(ISNUMBER(AG16),ISNUMBER(AM16),ISNUMBER(CC16),ISNUMBER(CH16))),"Yes","No") -> Yes | F16: =31+25+19+25 -> 100 | G16: Unclear | H16: Unclear | I16: Unclear | J16: =16+14 -> 30 | K16: =17+10 -> 27 | L16: =23+20 -> 43 | M16: =F16 -> 100 | V16: =F16 -> 100 | AB16: =16+8 -> 24 | AC16: =40+36 -> 76 | AF16: =31+25+19+25 -> 100 | AG16: =31+25 -> 56 | AL16: =ROUND(AG16*(1-0.91),0) -> 5 | AM16: =ROUND(AG16*(1-0.73),0) -> 15 | BA16: =IF(ISNUMBER(BQ16),BQ16,IF(AND(ISNUMBER($BJ16),ISNUMBER($BK16)),BI16,"")) -> 1.08 | BB16: =IF(ISNUMBER(BR16),BR16,IF(AND(ISNUMBER($BJ16),ISNUMBER($BK16)),BJ16,"")) -> 0.6 | BC16: =IF(ISNUMBER(BS16),BS16,IF(AND(ISNUMBER($BJ16),ISNUMBER($BK16)),BK16,"")) -> 1.94 | BD16: =IF(ISNUMBER(BT16),BT16,IF(AND(ISNUMBER($BO16),ISNUMBER($BP16)),BN16,"")) -> 1.81 | BE16: =IF(ISNUMBER(BU16),BU16,IF(AND(ISNUMBER($BO16),ISNUMBER($BP16)),BO16,"")) -> 1.07 | BF16: =IF(ISNUMBER(BV16),BV16,IF(AND(ISNUMBER($BO16),ISNUMBER($BP16)),BP16,"")) -> 3.05 | BQ16: 1.08 | BR16: 0.6 | BS16: 1.94 | BT16: 1.81 | BU16: 1.07 | BV16: 3.05 | CC16: =19+25 -> 44 | CG16: =ROUND(CC16*(1-0.96),0) -> 2 | CH16: =ROUND(CC16*(1-0.82),0) -> 8 | CV16: "Neutrophil engraftment was defined as an absolute neutrophil count > 0.5 x 10^9/L for three consecutive days (the first of which was considered the engraftment day)" | CW16: "... platelet engraftment as a platelet count > 50 x 10^9/L for seven consecutive days (the first of which was considered engraftment day)" | CX16: Added 7/9/24
A17: Raouf MME | B17: 2023 | C17: https://pubmed.ncbi.nlm.nih.gov/36739398 | D17: =A17&" "&B17 -> Raouf MME 2023 | E17: =IF(OR(AND(ISNUMBER(AG17),ISNUMBER(AL17),ISNUMBER(CC17),ISNUMBER(CG17)),AND(ISNUMBER(AG17),ISNUMBER(AM17),ISNUMBER(CC17),ISNUMBER(CH17))),"Yes","No") -> Yes | F17: =25+15 -> 40 | G17: Unclear for whole cohort | H17: 19 | I17: 72 | J17: =1+11+17 -> 29 | K17: =11 -> 11 | M17: =12+28 -> 40 | T17: =12 -> 12 | AC17: =12+28 -> 40 | AF17: =25+15 -> 40 | AG17: 15 | AH17: Timing of IR failure relative to HHV-6 detection is unclear, but systemic testing was performed | AI17: 6 | AL17: 6 | AN17: 9 | AO17: 10 | AP17: 12 | AQ17: 15.5 | AR17: 28 | AS17: 8 | AT17: 10 | AU17: 11 | AV17: 12 | AW17: 13 | BA17: =IF(ISNUMBER(BQ17),BQ17,IF(AND(ISNUMBER($BJ17),ISNUMBER($BK17)),BI17,"")) | BB17: =IF(ISNUMBER(BR17),BR17,IF(AND(ISNUMBER($BJ17),ISNUMBER($BK17)),BJ17,"")) | BC17: =IF(ISNUMBER(BS17),BS17,IF(AND(ISNUMBER($BJ17),ISNUMBER($BK17)),BK17,"")) | BD17: =IF(ISNUMBER(BT17),BT17,IF(AND(ISNUMBER($BO17),ISNUMBER($BP17)),BN17,"")) | BE17: =IF(ISNUMBER(BU17),BU17,IF(AND(ISNUMBER($BO17),ISNUMBER($BP17)),BO17,"")) | BF17: =IF(ISNUMBER(BV17),BV17,IF(AND(ISNUMBER($BO17),ISNUMBER($BP17)),BP17,"")) | BG17: Unclear | BH17: Unclear | BI17: =CK17/AP17 -> 1 | BJ17: =IF(AND(ISNUMBER(BG17),ISNUMBER(BH17),ISNUMBER(BI17)),EXP(LOG(BI17)-1.96*SQRT((1/BG17)+(1/BH17))),"") | BK17: =IF(AND(ISNUMBER(BG17),ISNUMBER(BH17),ISNUMBER(BI17)),EXP(LOG(BI17)+1.96*SQRT((1/BG17)+(1/BH17))),"") | BL17: Unclear | BM17: Unclear | BN17: =CP17/AU17 -> 1.0909091 | BO17: =IF(AND(ISNUMBER(BL17),ISNUMBER(BM17),ISNUMBER(BN17)),EXP(LOG(BN17)-1.96*SQRT((1/BL17)+(1/BM17))),"") | BP17: =IF(AND(ISNUMBER(BL17),ISNUMBER(BM17),ISNUMBER(BN17)),EXP(LOG(BN17)+1.96*SQRT((1/BL17)+(1/BM17))),"") | BQ17: See note | BR17: See note | BS17: See note | CC17: 25 | CD17: 4 | CG17: 4 | CI17: 7 | CJ17: 11 | CK17: 12 | CL17: 13 | CM17: 24 | CN17: 5 | CO17: 11 | CP17: 12 | CQ17: 14 | CR17: 22 | CV17: Not defined | CX17: marked broad engraftment as neutrophil. Combines delayed engraftment and bone marrow suppression into one category. Odds given for delayed engraftment, which invert the interpretation
A18: Rapaport D | B18: 2002 | C18: https://pubmed.ncbi.nlm.nih.gov/12123421 | D18: =A18&" "&B18 -> Rapaport D 2002 | E18: =IF(OR(AND(ISNUMBER(AG18),ISNUMBER(AL18),ISNUMBER(CC18),ISNUMBER(CG18)),AND(ISNUMBER(AG18),ISNUMBER(AM18),ISNUMBER(CC18),ISNUMBER(CH18))),"Yes","No") -> Yes | F18: 14 | G18: =MEDIAN(21,17,36,40,12,35,40,21,11,48,36,18,29,23) -> 26 | H18: =MIN(21,17,36,40,12,35,40,21,11,48,36,18,29,23) -> 11 | I18: =MAX(21,17,36,40,12,35,40,21,11,48,36,18,29,23) -> 48 | L18: =F18 -> 14 | M18: =F18 -> 14 | T18: 5 | Z18: 8 | AG18: 3 | AH18: 0 | AI18: 1 | AL18: 1 | BA18: =IF(ISNUMBER(BQ18),BQ18,IF(AND(ISNUMBER($BJ18),ISNUMBER($BK18)),BI18,"")) | BB18: =IF(ISNUMBER(BR18),BR18,IF(AND(ISNUMBER($BJ18),ISNUMBER($BK18)),BJ18,"")) | BC18: =IF(ISNUMBER(BS18),BS18,IF(AND(ISNUMBER($BJ18),ISNUMBER($BK18)),BK18,"")) | BD18: =IF(ISNUMBER(BT18),BT18,IF(AND(ISNUMBER($BO18),ISNUMBER($BP18)),BN18,"")) | BE18: =IF(ISNUMBER(BU18),BU18,IF(AND(ISNUMBER($BO18),ISNUMBER($BP18)),BO18,"")) | BF18: =IF(ISNUMBER(BV18),BV18,IF(AND(ISNUMBER($BO18),ISNUMBER($BP18)),BP18,"")) | BJ18: =IF(AND(ISNUMBER(BG18),ISNUMBER(BH18),ISNUMBER(BI18)),EXP(LOG(BI18)-1.96*SQRT((1/BG18)+(1/BH18))),"") | BK18: =IF(AND(ISNUMBER(BG18),ISNUMBER(BH18),ISNUMBER(BI18)),EXP(LOG(BI18)+1.96*SQRT((1/BG18)+(1/BH18))),"") | BO18: =IF(AND(ISNUMBER(BL18),ISNUMBER(BM18),ISNUMBER(BN18)),EXP(LOG(BN18)-1.96*SQRT((1/BL18)+(1/BM18))),"") | BP18: =IF(AND(ISNUMBER(BL18),ISNUMBER(BM18),ISNUMBER(BN18)),EXP(LOG(BN18)+1.96*SQRT((1/BL18)+(1/BM18))),"") | CC18: =14-3 -> 11 | CD18: 5 | CG18: 5 | CV18: Cell level not defined. "... defining late engraftment as that occurring 18 days post-BMT" | CX18: marked broad engraftment as neutrophil
A19: Savolainen H | B19: 2005 | C19: https://pubmed.ncbi.nlm.nih.gov/15700258 | D19: =A19&" "&B19 -> Savolainen H 2005 | E19: =IF(OR(AND(ISNUMBER(AG19),ISNUMBER(AL19),ISNUMBER(CC19),ISNUMBER(CG19)),AND(ISNUMBER(AG19),ISNUMBER(AM19),ISNUMBER(CC19),ISNUMBER(CH19))),"Yes","No") -> Yes | F19: 60 | G19: Unclear for whole cohort | H19: 2 | I19: 20 | J19: =16+3 -> 19 | K19: =5+34+2+3 -> 44 | P19: =F19 -> 60 | AA19: =F19 -> 60 | AB19: =7+37 -> 44 | AC19: =14+2 -> 16 | AG19: 45 | AH19: 0 | AI19: 1 | AL19: 1 | AP19: 20 | AU19: 44 | BA19: =IF(ISNUMBER(BQ19),BQ19,IF(AND(ISNUMBER($BJ19),ISNUMBER($BK19)),BI19,"")) -> 0.7 | BB19: =IF(ISNUMBER(BR19),BR19,IF(AND(ISNUMBER($BJ19),ISNUMBER($BK19)),BJ19,"")) -> 0.47667574 | BC19: =IF(ISNUMBER(BS19),BS19,IF(AND(ISNUMBER($BJ19),ISNUMBER($BK19)),BK19,"")) -> 1.5389724 | BD19: =IF(ISNUMBER(BT19),BT19,IF(AND(ISNUMBER($BO19),ISNUMBER($BP19)),BN19,"")) -> 0.5 | BE19: =IF(ISNUMBER(BU19),BU19,IF(AND(ISNUMBER($BO19),ISNUMBER($BP19)),BO19,"")) -> 0.41187027 | BF19: =IF(ISNUMBER(BV19),BV19,IF(AND(ISNUMBER($BO19),ISNUMBER($BP19)),BP19,"")) -> 1.3297446 | BG19: =AG19-1 -> 44 | BH19: =CC19 -> 15 | BI19: =CK19/AP19 -> 0.7 | BJ19: =IF(AND(ISNUMBER(BG19),ISNUMBER(BH19),ISNUMBER(BI19)),EXP(LOG(BI19)-1.96*SQRT((1/BG19)+(1/BH19))),"") -> 0.47667574 | BK19: =IF(AND(ISNUMBER(BG19),ISNUMBER(BH19),ISNUMBER(BI19)),EXP(LOG(BI19)+1.96*SQRT((1/BG19)+(1/BH19))),"") -> 1.5389724 | BL19: =AG19-1 -> 44 | BM19: =CC19 -> 15 | BN19: =CP19/AU19 -> 0.5 | BO19: =IF(AND(ISNUMBER(BL19),ISNUMBER(BM19),ISNUMBER(BN19)),EXP(LOG(BN19)-1.96*SQRT((1/BL19)+(1/BM19))),"") -> 0.41187027 | BP19: =IF(AND(ISNUMBER(BL19),ISNUMBER(BM19),ISNUMBER(BN19)),EXP(LOG(BN19)+1.96*SQRT((1/BL19)+(1/BM19))),"") -> 1.3297446 | CC19: =F19-AG19 -> 15 | CD19: 0 | CG19: 0 | CK19: 14 | CP19: 22 | CX19: marked broad engraftment as neutrophil
A20: Violago L | B20: 2015 | C20: https://pubmed.ncbi.nlm.nih.gov/26329541 | D20: =A20&" "&B20 -> Violago L 2015 | E20: =IF(OR(AND(ISNUMBER(AG20),ISNUMBER(AL20),ISNUMBER(CC20),ISNUMBER(CG20)),AND(ISNUMBER(AG20),ISNUMBER(AM20),ISNUMBER(CC20),ISNUMBER(CH20))),"Yes","No") -> Yes | F20: 100 | G20: 9 | H20: 0.25 | I20: 22 | J20: =35+22 -> 57 | K20: 43 | M20: =F20 -> 100 | AA20: =F20 -> 100 | AB20: 49 | AC20: 30 | AD20: 21 | AF20: 100 | AG20: 19 | AH20: Timing of IR failure relative to HHV-6 detection is unclear, but systemic testing was performed | AL20: =ROUND(AG20*(1-0.85),0) -> 3 | AM20: =ROUND(AG20*(1-0.58),0) -> 8 | BA20: =IF(ISNUMBER(BQ20),BQ20,IF(AND(ISNUMBER($BJ20),ISNUMBER($BK20)),BI20,"")) | BB20: =IF(ISNUMBER(BR20),BR20,IF(AND(ISNUMBER($BJ20),ISNUMBER($BK20)),BJ20,"")) | BC20: =IF(ISNUMBER(BS20),BS20,IF(AND(ISNUMBER($BJ20),ISNUMBER($BK20)),BK20,"")) | BD20: =IF(ISNUMBER(BT20),BT20,IF(AND(ISNUMBER($BO20),ISNUMBER($BP20)),BN20,"")) -> 0.91 | BE20: =IF(ISNUMBER(BU20),BU20,IF(AND(ISNUMBER($BO20),ISNUMBER($BP20)),BO20,"")) -> 0.447 | BF20: =IF(ISNUMBER(BV20),BV20,IF(AND(ISNUMBER($BO20),ISNUMBER($BP20)),BP20,"")) -> 1.852 | BJ20: =IF(AND(ISNUMBER(BG20),ISNUMBER(BH20),ISNUMBER(BI20)),EXP(LOG(BI20)-1.96*SQRT((1/BG20)+(1/BH20))),"") | BK20: =IF(AND(ISNUMBER(BG20),ISNUMBER(BH20),ISNUMBER(BI20)),EXP(LOG(BI20)+1.96*SQRT((1/BG20)+(1/BH20))),"") | BO20: =IF(AND(ISNUMBER(BL20),ISNUMBER(BM20),ISNUMBER(BN20)),EXP(LOG(BN20)-1.96*SQRT((1/BL20)+(1/BM20))),"") | BP20: =IF(AND(ISNUMBER(BL20),ISNUMBER(BM20),ISNUMBER(BN20)),EXP(LOG(BN20)+1.96*SQRT((1/BL20)+(1/BM20))),"") | BT20: 0.91 | BU20: 0.447 | BV20: 1.852 | CC20: 81 | CG20: =ROUND(CC20*(1-0.74),0) -> 21 | CH20: =ROUND(CC20*(1-0.82),0) -> 15
A21: Wang FZ | B21: 1996 | C21: https://pubmed.ncbi.nlm.nih.gov/8896431 | D21: =A21&" "&B21 -> Wang FZ 1996 | E21: =IF(OR(AND(ISNUMBER(AG21),ISNUMBER(AL21),ISNUMBER(CC21),ISNUMBER(CG21)),AND(ISNUMBER(AG21),ISNUMBER(AM21),ISNUMBER(CC21),ISNUMBER(CH21))),"Yes","No") -> Yes | AG21: 8 | AH21: Timing of IR failure relative to HHV-6 detection is unclear, but systemic testing was performed | AL21: =1+2+1+1 -> 5 | BA21: =IF(ISNUMBER(BQ21),BQ21,IF(AND(ISNUMBER($BJ21),ISNUMBER($BK21)),BI21,"")) | BB21: =IF(ISNUMBER(BR21),BR21,IF(AND(ISNUMBER($BJ21),ISNUMBER($BK21)),BJ21,"")) | BC21: =IF(ISNUMBER(BS21),BS21,IF(AND(ISNUMBER($BJ21),ISNUMBER($BK21)),BK21,"")) | BD21: =IF(ISNUMBER(BT21),BT21,IF(AND(ISNUMBER($BO21),ISNUMBER($BP21)),BN21,"")) | BE21: =IF(ISNUMBER(BU21),BU21,IF(AND(ISNUMBER($BO21),ISNUMBER($BP21)),BO21,"")) | BF21: =IF(ISNUMBER(BV21),BV21,IF(AND(ISNUMBER($BO21),ISNUMBER($BP21)),BP21,"")) | BJ21: =IF(AND(ISNUMBER(BG21),ISNUMBER(BH21),ISNUMBER(BI21)),EXP(LOG(BI21)-1.96*SQRT((1/BG21)+(1/BH21))),"") | BK21: =IF(AND(ISNUMBER(BG21),ISNUMBER(BH21),ISNUMBER(BI21)),EXP(LOG(BI21)+1.96*SQRT((1/BG21)+(1/BH21))),"") | BO21: =IF(AND(ISNUMBER(BL21),ISNUMBER(BM21),ISNUMBER(BN21)),EXP(LOG(BN21)-1.96*SQRT((1/BL21)+(1/BM21))),"") | BP21: =IF(AND(ISNUMBER(BL21),ISNUMBER(BM21),ISNUMBER(BN21)),EXP(LOG(BN21)+1.96*SQRT((1/BL21)+(1/BM21))),"") | CC21: =37-8 -> 29 | CG21: 3
A22: Wang LR | B22: 2006 | C22: https://pubmed.ncbi.nlm.nih.gov/17067909 | D22: =A22&" "&B22 -> Wang LR 2006 | E22: =IF(OR(AND(ISNUMBER(AG22),ISNUMBER(AL22),ISNUMBER(CC22),ISNUMBER(CG22)),AND(ISNUMBER(AG22),ISNUMBER(AM22),ISNUMBER(CC22),ISNUMBER(CH22))),"Yes","No") -> Yes | F22: 72 | G22: 28 | H22: 8 | I22: 58 | J22: 25 | K22: 47 | M22: =F22 -> 72 | S22: =F22 -> 72 | AB22: =F22 -> 72 | AF22: 72 | AG22: 27 | AH22: Timing of IR failure relative to HHV-6 detection is unclear, but systemic testing was performed | AL22: 0 | AM22: 4 | BA22: =IF(ISNUMBER(BQ22),BQ22,IF(AND(ISNUMBER($BJ22),ISNUMBER($BK22)),BI22,"")) -> 2.28 | BB22: =IF(ISNUMBER(BR22),BR22,IF(AND(ISNUMBER($BJ22),ISNUMBER($BK22)),BJ22,"")) -> 0.86 | BC22: =IF(ISNUMBER(BS22),BS22,IF(AND(ISNUMBER($BJ22),ISNUMBER($BK22)),BK22,"")) -> 6.06 | BD22: =IF(ISNUMBER(BT22),BT22,IF(AND(ISNUMBER($BO22),ISNUMBER($BP22)),BN22,"")) -> 1.02 | BE22: =IF(ISNUMBER(BU22),BU22,IF(AND(ISNUMBER($BO22),ISNUMBER($BP22)),BO22,"")) -> 0.47 | BF22: =IF(ISNUMBER(BV22),BV22,IF(AND(ISNUMBER($BO22),ISNUMBER($BP22)),BP22,"")) -> 2.19 | BJ22: =IF(AND(ISNUMBER(BG22),ISNUMBER(BH22),ISNUMBER(BI22)),EXP(LOG(BI22)-1.96*SQRT((1/BG22)+(1/BH22))),"") | BK22: =IF(AND(ISNUMBER(BG22),ISNUMBER(BH22),ISNUMBER(BI22)),EXP(LOG(BI22)+1.96*SQRT((1/BG22)+(1/BH22))),"") | BO22: =IF(AND(ISNUMBER(BL22),ISNUMBER(BM22),ISNUMBER(BN22)),EXP(LOG(BN22)-1.96*SQRT((1/BL22)+(1/BM22))),"") | BP22: =IF(AND(ISNUMBER(BL22),ISNUMBER(BM22),ISNUMBER(BN22)),EXP(LOG(BN22)+1.96*SQRT((1/BL22)+(1/BM22))),"") | BQ22: 2.28 | BR22: 0.86 | BS22: 6.06 | BT22: 1.02 | BU22: 0.47 | BV22: 2.19 | CC22: =AF22-AG22 -> 45 | CG22: 1 | CH22: =45-31 -> 14 | CX22: Labeled 2006a in FTR. Day 50 HR's chosen
A23: Balsat M | B23: 2019 | C23: https://pubmed.ncbi.nlm.nih.gov/31075291 | D23: =A23&" "&B23 -> Balsat M 2019 | E23: =IF(OR(AND(ISNUMBER(AG23),ISNUMBER(AL23),ISNUMBER(CC23),ISNUMBER(CG23)),AND(ISNUMBER(AG23),ISNUMBER(AM23),ISNUMBER(CC23),ISNUMBER(CH23))),"Yes","No") -> No | AG23: 22 | AH23: Timing of IR failure relative to HHV-6 detection is unclear, but systemic testing was performed | AO23: 8 | AP23: 10 | AQ23: 14 | BA23: =IF(ISNUMBER(BQ23),BQ23,IF(AND(ISNUMBER($BJ23),ISNUMBER($BK23)),BI23,"")) -> 0.8 | BB23: =IF(ISNUMBER(BR23),BR23,IF(AND(ISNUMBER($BJ23),ISNUMBER($BK23)),BJ23,"")) -> 0.58250668 | BC23: =IF(ISNUMBER(BS23),BS23,IF(AND(ISNUMBER($BJ23),ISNUMBER($BK23)),BK23,"")) -> 1.4142433 | BD23: =IF(ISNUMBER(BT23),BT23,IF(AND(ISNUMBER($BO23),ISNUMBER($BP23)),BN23,"")) | BE23: =IF(ISNUMBER(BU23),BU23,IF(AND(ISNUMBER($BO23),ISNUMBER($BP23)),BO23,"")) | BF23: =IF(ISNUMBER(BV23),BV23,IF(AND(ISNUMBER($BO23),ISNUMBER($BP23)),BP23,"")) | BG23: =AG23*1 -> 22 | BH23: =CC23*1 -> 174 | BI23: =CK23/AP23 -> 0.8 | BJ23: =IF(AND(ISNUMBER(BG23),ISNUMBER(BH23),ISNUMBER(BI23)),EXP(LOG(BI23)-1.96*SQRT((1/BG23)+(1/BH23))),"") -> 0.58250668 | BK23: =IF(AND(ISNUMBER(BG23),ISNUMBER(BH23),ISNUMBER(BI23)),EXP(LOG(BI23)+1.96*SQRT((1/BG23)+(1/BH23))),"") -> 1.4142433 | BO23: =IF(AND(ISNUMBER(BL23),ISNUMBER(BM23),ISNUMBER(BN23)),EXP(LOG(BN23)-1.96*SQRT((1/BL23)+(1/BM23))),"") | BP23: =IF(AND(ISNUMBER(BL23),ISNUMBER(BM23),ISNUMBER(BN23)),EXP(LOG(BN23)+1.96*SQRT((1/BL23)+(1/BM23))),"") | CC23: 174 | CJ23: 6 | CK23: 8 | CL23: 11 | CV23: Neutropenia recovery was defined as absolute neutrophil count (ANC) > 0.5× 10^9/L for two consecutive days. | CW23: Platelets recovery was defined as platelets count > 20× 109/L without transfusion support.
A24: Inazawa N | B24: 2017 | C24: https://pubmed.ncbi.nlm.nih.gov/27364410 | D24: =A24&" "&B24 -> Inazawa N 2017 | E24: =IF(OR(AND(ISNUMBER(AG24),ISNUMBER(AL24),ISNUMBER(CC24),ISNUMBER(CG24)),AND(ISNUMBER(AG24),ISNUMBER(AM24),ISNUMBER(CC24),ISNUMBER(CH24))),"Yes","No") -> No | AG24: 9 | AH24: Timing of IR failure relative to HHV-6 detection is unclear, but systemic testing was performed | AN24: 8 | AP24: 11 | AR24: 15 | BA24: =IF(ISNUMBER(BQ24),BQ24,IF(AND(ISNUMBER($BJ24),ISNUMBER($BK24)),BI24,"")) -> 1.0909091 | BB24: =IF(ISNUMBER(BR24),BR24,IF(AND(ISNUMBER($BJ24),ISNUMBER($BK24)),BJ24,"")) -> 0.44391399 | BC24: =IF(ISNUMBER(BS24),BS24,IF(AND(ISNUMBER($BJ24),ISNUMBER($BK24)),BK24,"")) -> 2.4295391 | BD24: =IF(ISNUMBER(BT24),BT24,IF(AND(ISNUMBER($BO24),ISNUMBER($BP24)),BN24,"")) | BE24: =IF(ISNUMBER(BU24),BU24,IF(AND(ISNUMBER($BO24),ISNUMBER($BP24)),BO24,"")) | BF24: =IF(ISNUMBER(BV24),BV24,IF(AND(ISNUMBER($BO24),ISNUMBER($BP24)),BP24,"")) | BG24: 9 | BH24: 13 | BI24: =CK24/AP24 -> 1.0909091 | BJ24: =IF(AND(ISNUMBER(BG24),ISNUMBER(BH24),ISNUMBER(BI24)),EXP(LOG(BI24)-1.96*SQRT((1/BG24)+(1/BH24))),"") -> 0.44391399 | BK24: =IF(AND(ISNUMBER(BG24),ISNUMBER(BH24),ISNUMBER(BI24)),EXP(LOG(BI24)+1.96*SQRT((1/BG24)+(1/BH24))),"") -> 2.4295391 | BO24: =IF(AND(ISNUMBER(BL24),ISNUMBER(BM24),ISNUMBER(BN24)),EXP(LOG(BN24)-1.96*SQRT((1/BL24)+(1/BM24))),"") | BP24: =IF(AND(ISNUMBER(BL24),ISNUMBER(BM24),ISNUMBER(BN24)),EXP(LOG(BN24)+1.96*SQRT((1/BL24)+(1/BM24))),"") | CC24: 13 | CI24: 5 | CK24: 12 | CM24: 20 | CV24: Not defined
A25: Ishiyama K | B25: 2011 | C25: https://pubmed.ncbi.nlm.nih.gov/20838386 | D25: =A25&" "&B25 -> Ishiyama K 2011 | E25: =IF(OR(AND(ISNUMBER(AG25),ISNUMBER(AL25),ISNUMBER(CC25),ISNUMBER(CG25)),AND(ISNUMBER(AG25),ISNUMBER(AM25),ISNUMBER(CC25),ISNUMBER(CH25))),"Yes","No") -> No | AG25: 12 | AH25: Timing of IR failure relative to HHV-6 detection is unclear, but systemic testing was performed | AP25: 27 | BA25: =IF(ISNUMBER(BQ25),BQ25,IF(AND(ISNUMBER($BJ25),ISNUMBER($BK25)),BI25,"")) -> 0.92592593 | BB25: =IF(ISNUMBER(BR25),BR25,IF(AND(ISNUMBER($BJ25),ISNUMBER($BK25)),BJ25,"")) -> 0.27291406 | BC25: =IF(ISNUMBER(BS25),BS25,IF(AND(ISNUMBER($BJ25),ISNUMBER($BK25)),BK25,"")) -> 3.4272247 | BD25: =IF(ISNUMBER(BT25),BT25,IF(AND(ISNUMBER($BO25),ISNUMBER($BP25)),BN25,"")) | BE25: =IF(ISNUMBER(BU25),BU25,IF(AND(ISNUMBER($BO25),ISNUMBER($BP25)),BO25,"")) | BF25: =IF(ISNUMBER(BV25),BV25,IF(AND(ISNUMBER($BO25),ISNUMBER($BP25)),BP25,"")) | BG25: 12 | BH25: 3 | BI25: =CK25/AP25 -> 0.92592593 | BJ25: =IF(AND(ISNUMBER(BG25),ISNUMBER(BH25),ISNUMBER(BI25)),EXP(LOG(BI25)-1.96*SQRT((1/BG25)+(1/BH25))),"") -> 0.27291406 | BK25: =IF(AND(ISNUMBER(BG25),ISNUMBER(BH25),ISNUMBER(BI25)),EXP(LOG(BI25)+1.96*SQRT((1/BG25)+(1/BH25))),"") -> 3.4272247 | BO25: =IF(AND(ISNUMBER(BL25),ISNUMBER(BM25),ISNUMBER(BN25)),EXP(LOG(BN25)-1.96*SQRT((1/BL25)+(1/BM25))),"") | BP25: =IF(AND(ISNUMBER(BL25),ISNUMBER(BM25),ISNUMBER(BN25)),EXP(LOG(BN25)+1.96*SQRT((1/BL25)+(1/BM25))),"") | CC25: 3 | CK25: 25 | CV25: "... neutrophils >0.5 x 10^9/L"
A26: Olson AL | B26: 2014 | C26: https://pubmed.ncbi.nlm.nih.gov/24548875 | D26: =A26&" "&B26 -> Olson AL 2014 | E26: =IF(OR(AND(ISNUMBER(AG26),ISNUMBER(AL26),ISNUMBER(CC26),ISNUMBER(CG26)),AND(ISNUMBER(AG26),ISNUMBER(AM26),ISNUMBER(CC26),ISNUMBER(CH26))),"Yes","No") -> No | AG26: 51 | AH26: Timing of IR failure relative to HHV-6 detection is unclear, but systemic testing was performed | AN26: 7 | AP26: 22 | AR26: 38 | AS26: 32 | AU26: 48 | AW26: 99 | BA26: =IF(ISNUMBER(BQ26),BQ26,IF(AND(ISNUMBER($BJ26),ISNUMBER($BK26)),BI26,"")) -> 0.98 | BB26: =IF(ISNUMBER(BR26),BR26,IF(AND(ISNUMBER($BJ26),ISNUMBER($BK26)),BJ26,"")) -> 0.68 | BC26: =IF(ISNUMBER(BS26),BS26,IF(AND(ISNUMBER($BJ26),ISNUMBER($BK26)),BK26,"")) -> 1.41 | BD26: =IF(ISNUMBER(BT26),BT26,IF(AND(ISNUMBER($BO26),ISNUMBER($BP26)),BN26,"")) -> 1.01 | BE26: =IF(ISNUMBER(BU26),BU26,IF(AND(ISNUMBER($BO26),ISNUMBER($BP26)),BO26,"")) -> 0.68 | BF26: =IF(ISNUMBER(BV26),BV26,IF(AND(ISNUMBER($BO26),ISNUMBER($BP26)),BP26,"")) -> 1.5 | BG26: Unclear | BH26: Unclear | BI26: =CK26/AP26 -> 0.95454545 | BJ26: =IF(AND(ISNUMBER(BG26),ISNUMBER(BH26),ISNUMBER(BI26)),EXP(LOG(BI26)-1.96*SQRT((1/BG26)+(1/BH26))),"") | BK26: =IF(AND(ISNUMBER(BG26),ISNUMBER(BH26),ISNUMBER(BI26)),EXP(LOG(BI26)+1.96*SQRT((1/BG26)+(1/BH26))),"") | BL26: Unclear | BM26: Unclear | BN26: =CP26/AU26 -> 0.95833333 | BO26: =IF(AND(ISNUMBER(BL26),ISNUMBER(BM26),ISNUMBER(BN26)),EXP(LOG(BN26)-1.96*SQRT((1/BL26)+(1/BM26))),"") | BP26: =IF(AND(ISNUMBER(BL26),ISNUMBER(BM26),ISNUMBER(BN26)),EXP(LOG(BN26)+1.96*SQRT((1/BL26)+(1/BM26))),"") | BQ26: 0.98 | BR26: 0.68 | BS26: 1.41 | BT26: 1.01 | BU26: 0.68 | BV26: 1.5 | CC26: 74 | CI26: 7 | CK26: 21 | CM26: 43 | CN26: 21 | CP26: 46 | CR26: 90 | CV26: Not defined
A27: Quintela A | B27: 2016 | C27: https://pubmed.ncbi.nlm.nih.gov/26518057 | D27: =A27&" "&B27 -> Quintela A 2016 | E27: =IF(OR(AND(ISNUMBER(AG27),ISNUMBER(AL27),ISNUMBER(CC27),ISNUMBER(CG27)),AND(ISNUMBER(AG27),ISNUMBER(AM27),ISNUMBER(CC27),ISNUMBER(CH27))),"Yes","No") -> No | AG27: 75 | AH27: Timing of IR failure relative to HHV-6 detection is unclear | AN27: 8 | AP27: 24 | AR27: 43 | BA27: =IF(ISNUMBER(BQ27),BQ27,IF(AND(ISNUMBER($BJ27),ISNUMBER($BK27)),BI27,"")) | BB27: =IF(ISNUMBER(BR27),BR27,IF(AND(ISNUMBER($BJ27),ISNUMBER($BK27)),BJ27,"")) | BC27: =IF(ISNUMBER(BS27),BS27,IF(AND(ISNUMBER($BJ27),ISNUMBER($BK27)),BK27,"")) | BD27: =IF(ISNUMBER(BT27),BT27,IF(AND(ISNUMBER($BO27),ISNUMBER($BP27)),BN27,"")) | BE27: =IF(ISNUMBER(BU27),BU27,IF(AND(ISNUMBER($BO27),ISNUMBER($BP27)),BO27,"")) | BF27: =IF(ISNUMBER(BV27),BV27,IF(AND(ISNUMBER($BO27),ISNUMBER($BP27)),BP27,"")) | BG27: Unclear | BH27: Unclear | BI27: =CK27/AP27 -> 0.83333333 | BJ27: =IF(AND(ISNUMBER(BG27),ISNUMBER(BH27),ISNUMBER(BI27)),EXP(LOG(BI27)-1.96*SQRT((1/BG27)+(1/BH27))),"") | BK27: =IF(AND(ISNUMBER(BG27),ISNUMBER(BH27),ISNUMBER(BI27)),EXP(LOG(BI27)+1.96*SQRT((1/BG27)+(1/BH27))),"") | BO27: =IF(AND(ISNUMBER(BL27),ISNUMBER(BM27),ISNUMBER(BN27)),EXP(LOG(BN27)-1.96*SQRT((1/BL27)+(1/BM27))),"") | BP27: =IF(AND(ISNUMBER(BL27),ISNUMBER(BM27),ISNUMBER(BN27)),EXP(LOG(BN27)+1.96*SQRT((1/BL27)+(1/BM27))),"") | CC27: 291 | CI27: 2 | CK27: 20 | CM27: 48 | CV27: Not defined
A28: Tormo N | B28: 2010 | C28: https://pubmed.ncbi.nlm.nih.gov/20005968 | D28: =A28&" "&B28 -> Tormo N 2010 | E28: =IF(OR(AND(ISNUMBER(AG28),ISNUMBER(AL28),ISNUMBER(CC28),ISNUMBER(CG28)),AND(ISNUMBER(AG28),ISNUMBER(AM28),ISNUMBER(CC28),ISNUMBER(CH28))),"Yes","No") -> No | AH28: Timing of IR failure relative to HHV-6 detection is unclear | BA28: =IF(ISNUMBER(BQ28),BQ28,IF(AND(ISNUMBER($BJ28),ISNUMBER($BK28)),BI28,"")) -> 1 | BB28: =IF(ISNUMBER(BR28),BR28,IF(AND(ISNUMBER($BJ28),ISNUMBER($BK28)),BJ28,"")) -> 0.8 | BC28: =IF(ISNUMBER(BS28),BS28,IF(AND(ISNUMBER($BJ28),ISNUMBER($BK28)),BK28,"")) -> 1.7 | BD28: =IF(ISNUMBER(BT28),BT28,IF(AND(ISNUMBER($BO28),ISNUMBER($BP28)),BN28,"")) -> 0.9 | BE28: =IF(ISNUMBER(BU28),BU28,IF(AND(ISNUMBER($BO28),ISNUMBER($BP28)),BO28,"")) -> 0.7 | BF28: =IF(ISNUMBER(BV28),BV28,IF(AND(ISNUMBER($BO28),ISNUMBER($BP28)),BP28,"")) -> 2.1 | BJ28: =IF(AND(ISNUMBER(BG28),ISNUMBER(BH28),ISNUMBER(BI28)),EXP(LOG(BI28)-1.96*SQRT((1/BG28)+(1/BH28))),"") | BK28: =IF(AND(ISNUMBER(BG28),ISNUMBER(BH28),ISNUMBER(BI28)),EXP(LOG(BI28)+1.96*SQRT((1/BG28)+(1/BH28))),"") | BO28: =IF(AND(ISNUMBER(BL28),ISNUMBER(BM28),ISNUMBER(BN28)),EXP(LOG(BN28)-1.96*SQRT((1/BL28)+(1/BM28))),"") | BP28: =IF(AND(ISNUMBER(BL28),ISNUMBER(BM28),ISNUMBER(BN28)),EXP(LOG(BN28)+1.96*SQRT((1/BL28)+(1/BM28))),"") | BQ28: 1 | BR28: 0.8 | BS28: 1.7 | BT28: 0.9 | BU28: 0.7 | BV28: 2.1
A29: Yoshikawa T | B29: 2002 | C29: https://pubmed.ncbi.nlm.nih.gov/11920307 | D29: =A29&" "&B29 -> Yoshikawa T 2002 | E29: =IF(OR(AND(ISNUMBER(AG29),ISNUMBER(AL29),ISNUMBER(CC29),ISNUMBER(CG29)),AND(ISNUMBER(AG29),ISNUMBER(AM29),ISNUMBER(CC29),ISNUMBER(CH29))),"Yes","No") -> No | AG29: 31 | AH29: Timing of IR failure relative to HHV-6 detection is unclear, but systemic testing was performed | AN29: 10 | AP29: 17.3 | AR29: 38 | AS29: 16 | AU29: 31 | AW29: 60 | BA29: =IF(ISNUMBER(BQ29),BQ29,IF(AND(ISNUMBER($BJ29),ISNUMBER($BK29)),BI29,"")) | BB29: =IF(ISNUMBER(BR29),BR29,IF(AND(ISNUMBER($BJ29),ISNUMBER($BK29)),BJ29,"")) | BC29: =IF(ISNUMBER(BS29),BS29,IF(AND(ISNUMBER($BJ29),ISNUMBER($BK29)),BK29,"")) | BD29: =IF(ISNUMBER(BT29),BT29,IF(AND(ISNUMBER($BO29),ISNUMBER($BP29)),BN29,"")) | BE29: =IF(ISNUMBER(BU29),BU29,IF(AND(ISNUMBER($BO29),ISNUMBER($BP29)),BO29,"")) | BF29: =IF(ISNUMBER(BV29),BV29,IF(AND(ISNUMBER($BO29),ISNUMBER($BP29)),BP29,"")) | BG29: Unclear | BH29: Unclear | BI29: =CK29/AP29 -> 1.0115607 | BJ29: =IF(AND(ISNUMBER(BG29),ISNUMBER(BH29),ISNUMBER(BI29)),EXP(LOG(BI29)-1.96*SQRT((1/BG29)+(1/BH29))),"") | BK29: =IF(AND(ISNUMBER(BG29),ISNUMBER(BH29),ISNUMBER(BI29)),EXP(LOG(BI29)+1.96*SQRT((1/BG29)+(1/BH29))),"") | BL29: Unclear | BM29: Unclear | BN29: =CP29/AU29 -> 0.83870968 | BO29: =IF(AND(ISNUMBER(BL29),ISNUMBER(BM29),ISNUMBER(BN29)),EXP(LOG(BN29)-1.96*SQRT((1/BL29)+(1/BM29))),"") | BP29: =IF(AND(ISNUMBER(BL29),ISNUMBER(BM29),ISNUMBER(BN29)),EXP(LOG(BN29)+1.96*SQRT((1/BL29)+(1/BM29))),"") | CC29: 51 | CI29: 12 | CK29: 17.5 | CM29: 60 | CN29: 8 | CP29: 26 | CR29: 60
A30: Zerr DM | B30: 2005 | C30: https://pubmed.ncbi.nlm.nih.gov/15824982 | D30: =A30&" "&B30 -> Zerr DM 2005 | E30: =IF(OR(AND(ISNUMBER(AG30),ISNUMBER(AL30),ISNUMBER(CC30),ISNUMBER(CG30)),AND(ISNUMBER(AG30),ISNUMBER(AM30),ISNUMBER(CC30),ISNUMBER(CH30))),"Yes","No") -> No | AH30: Timing of IR failure relative to HHV-6 detection is unclear, but systemic testing was performed | BA30: =IF(ISNUMBER(BQ30),BQ30,IF(AND(ISNUMBER($BJ30),ISNUMBER($BK30)),BI30,"")) -> 1 | BB30: =IF(ISNUMBER(BR30),BR30,IF(AND(ISNUMBER($BJ30),ISNUMBER($BK30)),BJ30,"")) -> 0.46 | BC30: =IF(ISNUMBER(BS30),BS30,IF(AND(ISNUMBER($BJ30),ISNUMBER($BK30)),BK30,"")) -> 1.7 | BD30: =IF(ISNUMBER(BT30),BT30,IF(AND(ISNUMBER($BO30),ISNUMBER($BP30)),BN30,"")) -> 0.43 | BE30: =IF(ISNUMBER(BU30),BU30,IF(AND(ISNUMBER($BO30),ISNUMBER($BP30)),BO30,"")) -> 0.19 | BF30: =IF(ISNUMBER(BV30),BV30,IF(AND(ISNUMBER($BO30),ISNUMBER($BP30)),BP30,"")) -> 0.97 | BJ30: =IF(AND(ISNUMBER(BG30),ISNUMBER(BH30),ISNUMBER(BI30)),EXP(LOG(BI30)-1.96*SQRT((1/BG30)+(1/BH30))),"") | BK30: =IF(AND(ISNUMBER(BG30),ISNUMBER(BH30),ISNUMBER(BI30)),EXP(LOG(BI30)+1.96*SQRT((1/BG30)+(1/BH30))),"") | BO30: =IF(AND(ISNUMBER(BL30),ISNUMBER(BM30),ISNUMBER(BN30)),EXP(LOG(BN30)-1.96*SQRT((1/BL30)+(1/BM30))),"") | BP30: =IF(AND(ISNUMBER(BL30),ISNUMBER(BM30),ISNUMBER(BN30)),EXP(LOG(BN30)+1.96*SQRT((1/BL30)+(1/BM30))),"") | BQ30: 1 | BR30: 0.46 | BS30: 1.7 | BT30: 0.43 | BU30: 0.19 | BV30: 0.97 | CX30: Day 30 used for HR
A31: Chevallier P | B31: 2010 | C31: https://pubmed.ncbi.nlm.nih.gov/19935727 | D31: =A31&" "&B31 -> Chevallier P 2010 | E31: =IF(OR(AND(ISNUMBER(AL31),ISNUMBER(CG31)),AND(ISNUMBER(AM31),ISNUMBER(CH31)),AND(ISNUMBER(AP31),ISNUMBER(AN31),ISNUMBER(AR31),ISNUMBER(CK31),ISNUMBER(CI31),ISNUMBER(CM31)),AND(ISNUMBER(AU31),ISNUMBER(AS31),ISNUMBER(AW31),ISNUMBER(CP31),ISNUMBER(CN31),ISNUMBER(CR31)),AND(ISNUMBER(BB31),ISNUMBER(BC31))),"Yes","No") -> No | AG31: =12+17 -> 29 | AP31: 37.5 | AU31: 98.5 | BA31: =IF(ISNUMBER(BQ31),BQ31,IF(AND(ISNUMBER($BJ31),ISNUMBER($BK31)),BI31,"")) | BB31: =IF(ISNUMBER(BR31),BR31,IF(AND(ISNUMBER($BJ31),ISNUMBER($BK31)),BJ31,"")) | BC31: =IF(ISNUMBER(BS31),BS31,IF(AND(ISNUMBER($BJ31),ISNUMBER($BK31)),BK31,"")) | BD31: =IF(ISNUMBER(BT31),BT31,IF(AND(ISNUMBER($BO31),ISNUMBER($BP31)),BN31,"")) | BE31: =IF(ISNUMBER(BU31),BU31,IF(AND(ISNUMBER($BO31),ISNUMBER($BP31)),BO31,"")) | BF31: =IF(ISNUMBER(BV31),BV31,IF(AND(ISNUMBER($BO31),ISNUMBER($BP31)),BP31,"")) | BG31: Unclear | BH31: Unclear | BI31: =CK31/AP31 -> 0.44 | BJ31: =IF(AND(ISNUMBER(BG31),ISNUMBER(BH31),ISNUMBER(BI31)),EXP(LOG(BI31)-1.96*SQRT((1/BG31)+(1/BH31))),"") | BK31: =IF(AND(ISNUMBER(BG31),ISNUMBER(BH31),ISNUMBER(BI31)),EXP(LOG(BI31)+1.96*SQRT((1/BG31)+(1/BH31))),"") | BL31: Unclear | BM31: Unclear | BN31: =CP31/AU31 -> 0.12690355 | BO31: =IF(AND(ISNUMBER(BL31),ISNUMBER(BM31),ISNUMBER(BN31)),EXP(LOG(BN31)-1.96*SQRT((1/BL31)+(1/BM31))),"") | BP31: =IF(AND(ISNUMBER(BL31),ISNUMBER(BM31),ISNUMBER(BN31)),EXP(LOG(BN31)+1.96*SQRT((1/BL31)+(1/BM31))),"") | CC31: =15+40 -> 55 | CK31: 16.5 | CP31: 12.5
A32: Cirrone F | B32: 2016 | C32: https://pubmed.ncbi.nlm.nih.gov/26984480 | D32: =A32&" "&B32 -> Cirrone F 2016 | E32: =IF(OR(AND(ISNUMBER(AL32),ISNUMBER(CG32)),AND(ISNUMBER(AM32),ISNUMBER(CH32)),AND(ISNUMBER(AP32),ISNUMBER(AN32),ISNUMBER(AR32),ISNUMBER(CK32),ISNUMBER(CI32),ISNUMBER(CM32)),AND(ISNUMBER(AU32),ISNUMBER(AS32),ISNUMBER(AW32),ISNUMBER(CP32),ISNUMBER(CN32),ISNUMBER(CR32)),AND(ISNUMBER(BB32),ISNUMBER(BC32))),"Yes","No") -> No | AG32: 60 | AP32: 14 | AU32: 20 | BA32: =IF(ISNUMBER(BQ32),BQ32,IF(AND(ISNUMBER($BJ32),ISNUMBER($BK32)),BI32,"")) | BB32: =IF(ISNUMBER(BR32),BR32,IF(AND(ISNUMBER($BJ32),ISNUMBER($BK32)),BJ32,"")) | BC32: =IF(ISNUMBER(BS32),BS32,IF(AND(ISNUMBER($BJ32),ISNUMBER($BK32)),BK32,"")) | BD32: =IF(ISNUMBER(BT32),BT32,IF(AND(ISNUMBER($BO32),ISNUMBER($BP32)),BN32,"")) | BE32: =IF(ISNUMBER(BU32),BU32,IF(AND(ISNUMBER($BO32),ISNUMBER($BP32)),BO32,"")) | BF32: =IF(ISNUMBER(BV32),BV32,IF(AND(ISNUMBER($BO32),ISNUMBER($BP32)),BP32,"")) | BG32: Unclear | BH32: Unclear | BI32: =CK32/AP32 -> 1 | BJ32: =IF(AND(ISNUMBER(BG32),ISNUMBER(BH32),ISNUMBER(BI32)),EXP(LOG(BI32)-1.96*SQRT((1/BG32)+(1/BH32))),"") | BK32: =IF(AND(ISNUMBER(BG32),ISNUMBER(BH32),ISNUMBER(BI32)),EXP(LOG(BI32)+1.96*SQRT((1/BG32)+(1/BH32))),"") | BL32: Unclear | BM32: Unclear | BN32: =CP32/AU32 -> 1.15 | BO32: =IF(AND(ISNUMBER(BL32),ISNUMBER(BM32),ISNUMBER(BN32)),EXP(LOG(BN32)-1.96*SQRT((1/BL32)+(1/BM32))),"") | BP32: =IF(AND(ISNUMBER(BL32),ISNUMBER(BM32),ISNUMBER(BN32)),EXP(LOG(BN32)+1.96*SQRT((1/BL32)+(1/BM32))),"") | CC32: =92-60 -> 32 | CK32: 14 | CP32: 23
A33: de Koning C | B33: 2018 | C33: https://pubmed.ncbi.nlm.nih.gov/29487057 | D33: =A33&" "&B33 -> de Koning C 2018 | E33: =IF(OR(AND(ISNUMBER(AL33),ISNUMBER(CG33)),AND(ISNUMBER(AM33),ISNUMBER(CH33)),AND(ISNUMBER(AP33),ISNUMBER(AN33),ISNUMBER(AR33),ISNUMBER(CK33),ISNUMBER(CI33),ISNUMBER(CM33)),AND(ISNUMBER(AU33),ISNUMBER(AS33),ISNUMBER(AW33),ISNUMBER(CP33),ISNUMBER(CN33),ISNUMBER(CR33)),AND(ISNUMBER(BB33),ISNUMBER(BC33))),"Yes","No") -> No | AG33: 79 | AY33: 84 | BA33: =IF(ISNUMBER(BQ33),BQ33,IF(AND(ISNUMBER($BJ33),ISNUMBER($BK33)),BI33,"")) | BB33: =IF(ISNUMBER(BR33),BR33,IF(AND(ISNUMBER($BJ33),ISNUMBER($BK33)),BJ33,"")) | BC33: =IF(ISNUMBER(BS33),BS33,IF(AND(ISNUMBER($BJ33),ISNUMBER($BK33)),BK33,"")) | BD33: =IF(ISNUMBER(BT33),BT33,IF(AND(ISNUMBER($BO33),ISNUMBER($BP33)),BN33,"")) | BE33: =IF(ISNUMBER(BU33),BU33,IF(AND(ISNUMBER($BO33),ISNUMBER($BP33)),BO33,"")) | BF33: =IF(ISNUMBER(BV33),BV33,IF(AND(ISNUMBER($BO33),ISNUMBER($BP33)),BP33,"")) | BJ33: =IF(AND(ISNUMBER(BG33),ISNUMBER(BH33),ISNUMBER(BI33)),EXP(LOG(BI33)-1.96*SQRT((1/BG33)+(1/BH33))),"") | BK33: =IF(AND(ISNUMBER(BG33),ISNUMBER(BH33),ISNUMBER(BI33)),EXP(LOG(BI33)+1.96*SQRT((1/BG33)+(1/BH33))),"") | BO33: =IF(AND(ISNUMBER(BL33),ISNUMBER(BM33),ISNUMBER(BN33)),EXP(LOG(BN33)-1.96*SQRT((1/BL33)+(1/BM33))),"") | BP33: =IF(AND(ISNUMBER(BL33),ISNUMBER(BM33),ISNUMBER(BN33)),EXP(LOG(BN33)+1.96*SQRT((1/BL33)+(1/BM33))),"") | BW33: 0.913 | BX33: 0.892 | BY33: 0.934 | BZ33: 0.912 | CA33: 0.891 | CB33: 0.933 | CC33: =273-AG33 -> 194 | CT33: 78
A34: de Pagter AP | B34: 2012 | C34: https://pubmed.ncbi.nlm.nih.gov/22820131 | D34: =A34&" "&B34 -> de Pagter AP 2012 | E34: =IF(OR(AND(ISNUMBER(AL34),ISNUMBER(CG34)),AND(ISNUMBER(AM34),ISNUMBER(CH34)),AND(ISNUMBER(AP34),ISNUMBER(AN34),ISNUMBER(AR34),ISNUMBER(CK34),ISNUMBER(CI34),ISNUMBER(CM34)),AND(ISNUMBER(AU34),ISNUMBER(AS34),ISNUMBER(AW34),ISNUMBER(CP34),ISNUMBER(CN34),ISNUMBER(CR34)),AND(ISNUMBER(BB34),ISNUMBER(BC34))),"Yes","No") -> No | BA34: =IF(ISNUMBER(BQ34),BQ34,IF(AND(ISNUMBER($BJ34),ISNUMBER($BK34)),BI34,"")) | BB34: =IF(ISNUMBER(BR34),BR34,IF(AND(ISNUMBER($BJ34),ISNUMBER($BK34)),BJ34,"")) | BC34: =IF(ISNUMBER(BS34),BS34,IF(AND(ISNUMBER($BJ34),ISNUMBER($BK34)),BK34,"")) | BD34: =IF(ISNUMBER(BT34),BT34,IF(AND(ISNUMBER($BO34),ISNUMBER($BP34)),BN34,"")) | BE34: =IF(ISNUMBER(BU34),BU34,IF(AND(ISNUMBER($BO34),ISNUMBER($BP34)),BO34,"")) | BF34: =IF(ISNUMBER(BV34),BV34,IF(AND(ISNUMBER($BO34),ISNUMBER($BP34)),BP34,"")) | BJ34: =IF(AND(ISNUMBER(BG34),ISNUMBER(BH34),ISNUMBER(BI34)),EXP(LOG(BI34)-1.96*SQRT((1/BG34)+(1/BH34))),"") | BK34: =IF(AND(ISNUMBER(BG34),ISNUMBER(BH34),ISNUMBER(BI34)),EXP(LOG(BI34)+1.96*SQRT((1/BG34)+(1/BH34))),"") | BO34: =IF(AND(ISNUMBER(BL34),ISNUMBER(BM34),ISNUMBER(BN34)),EXP(LOG(BN34)-1.96*SQRT((1/BL34)+(1/BM34))),"") | BP34: =IF(AND(ISNUMBER(BL34),ISNUMBER(BM34),ISNUMBER(BN34)),EXP(LOG(BN34)+1.96*SQRT((1/BL34)+(1/BM34))),"")
A35: Dulery R | B35: 2012 | C35: https://pubmed.ncbi.nlm.nih.gov/22212513 | D35: =A35&" "&B35 -> Dulery R 2012 | E35: =IF(OR(AND(ISNUMBER(AL35),ISNUMBER(CG35)),AND(ISNUMBER(AM35),ISNUMBER(CH35)),AND(ISNUMBER(AP35),ISNUMBER(AN35),ISNUMBER(AR35),ISNUMBER(CK35),ISNUMBER(CI35),ISNUMBER(CM35)),AND(ISNUMBER(AU35),ISNUMBER(AS35),ISNUMBER(AW35),ISNUMBER(CP35),ISNUMBER(CN35),ISNUMBER(CR35)),AND(ISNUMBER(BB35),ISNUMBER(BC35))),"Yes","No") -> No | AG35: 112 | AU35: 29 | BA35: =IF(ISNUMBER(BQ35),BQ35,IF(AND(ISNUMBER($BJ35),ISNUMBER($BK35)),BI35,"")) | BB35: =IF(ISNUMBER(BR35),BR35,IF(AND(ISNUMBER($BJ35),ISNUMBER($BK35)),BJ35,"")) | BC35: =IF(ISNUMBER(BS35),BS35,IF(AND(ISNUMBER($BJ35),ISNUMBER($BK35)),BK35,"")) | BD35: =IF(ISNUMBER(BT35),BT35,IF(AND(ISNUMBER($BO35),ISNUMBER($BP35)),BN35,"")) | BE35: =IF(ISNUMBER(BU35),BU35,IF(AND(ISNUMBER($BO35),ISNUMBER($BP35)),BO35,"")) | BF35: =IF(ISNUMBER(BV35),BV35,IF(AND(ISNUMBER($BO35),ISNUMBER($BP35)),BP35,"")) | BJ35: =IF(AND(ISNUMBER(BG35),ISNUMBER(BH35),ISNUMBER(BI35)),EXP(LOG(BI35)-1.96*SQRT((1/BG35)+(1/BH35))),"") | BK35: =IF(AND(ISNUMBER(BG35),ISNUMBER(BH35),ISNUMBER(BI35)),EXP(LOG(BI35)+1.96*SQRT((1/BG35)+(1/BH35))),"") | BL35: Unclear | BM35: Unclear | BN35: =CP35/AU35 -> 0.75862069 | BO35: =IF(AND(ISNUMBER(BL35),ISNUMBER(BM35),ISNUMBER(BN35)),EXP(LOG(BN35)-1.96*SQRT((1/BL35)+(1/BM35))),"") | BP35: =IF(AND(ISNUMBER(BL35),ISNUMBER(BM35),ISNUMBER(BN35)),EXP(LOG(BN35)+1.96*SQRT((1/BL35)+(1/BM35))),"") | BT35: See note | BU35: see note | BV35: see note | CC35: 123 | CP35: 22 | CX35: Has HR for platelet, but inverts the conventional direction so that >1 corresponds to delay
